Workbook

Sheet Running Progress
A1: Technicians in Rentals - Holman Reporting
CW2: ** Change in Rental Reporting
A3: Rental Update-8/29-Benchmark | D3: Rental Update - 9/2 | H3: Rental Update - 9/3 | L3: Rental Update - 9/5 | P3: Rental Update - 9/16 | T3: Rental Update - 9/17 | X3: Rental Update - 9/18 | AB3: Rental Update - 9/19 | AF3: Rental Update - 9/20 | AJ3: Rental Update - 9/21 | AN3: Rental Update - 9/22 | AR3: Rental Update - 9/23 | AV3: Rental Update - 9/24 | AZ3: Rental Update - 9/29 | BD3: Rental Update - 9/30 | BH3: Rental Update - 10/1 | BL3: Rental Update - 10/2 | BP3: Rental Update - 10/3 | BT3: Rental Update - 10/6 | BX3: Rental Update - 10/7 | CB3: Rental Update - 10/9 | CF3: Rental Update - 10/10 | CJ3: Rental Update - 10/13 | CN3: Rental Update - 10/14 | CR3: Rental Update - 10/15 | CV3: Rental Update - 10/16 | CZ3: Rental Update - 10/17 | DD3: Rental Update - 10/20 | DH3: Rental Update - 10/21 | DL3: Rental Update - 10/22 | DP3: Rental Update - 10/23 | DT3: Rental Update - 10/24 | DX3: Rental Update - 10/27 | EB3: Rental Update - 10/28 | EF3: Rental Update - 10/29 | EJ3: Rental Update - 10/30 | EN3: Rental Update - 10/31 | ER3: Rental Update - 11/3 | EV3: Rental Update - 11/4 | EZ3: Rental Update - 11/5 | FD3: Rental Update - 11/6 | FH3: Rental Update - 11/7 | FL3: Rental Update - 11/10 | FP3: Rental Update - 11/11 | FT3: Rental Update - 11/12 | FX3: Rental Update - 11/13 | GB3: Rental Update - 11/17 | GF3: Rental Update - 11/18 | GJ3: Rental Update - 11/19 | GN3: Rental Update - 11/20 | GR3: Rental Update - 11/21 | GV3: Rental Update - 11/24 | GZ3: Rental Update - 11/25 | HD3: Rental Update - 11/26 | HH3: Rental Update - 12/1 | HL3: Rental Update - 12/2 | HP3: Rental Update - 12/3 | HT3: Rental Update - 12/4 | HX3: Rental Update - 12/5 | IB3: Rental Update - 12/8 | IF3: Rental Update - 12/9 | IJ3: Rental Update - 12/10 | IN3: Rental Update - 12/11 | IR3: Rental Update - 12/12 | IV3: Rental Update - 12/15 | IZ3: Rental Update - 12/16 | JD3: Rental Update - 12/17 | JH3: Rental Update - 12/18 | JL3: Rental Update - 12/19 | JP3: Rental Update - 12/22 | JT3: Rental Update - 12/23 | JX3: Rental Update - 12/24 | KB3: Rental Update - 12/25 | KF3: Rental Update - 12/26 | KJ3: Rental Update - 12/29 | KN3: Rental Update - 12/30 | KR3: Rental Update - 12/31 | KV3: Rental Update - 1/01 New Years Day Holiday | KZ3: Rental Update - 1/02 | LD3: Rental Update - 1/05 | LH3: Rental Update - 1/06 | LL3: Rental Update - 1/07 | LP3: Rental Update - 1/08 | LT3: Rental Update - 1/09 | LX3: Rental Update - 1/12 | MB3: Rental Update - 1/13 | MF3: Rental Update - 1/14 | MJ3: Rental Update - 1/15 | MN3: Rental Update - 1/16 | MR3: Rental Update - 1/19 | MV3: Rental Update - 1/20 | MZ3: Rental Update - 1/21 | ND3: Rental Update - 1/22 | NH3: Rental Update - 1/23 | NL3: Rental Update - 1/26 | NP3: Rental Update - 1/27 | NT3: Rental Update - 1/28 | NX3: Rental Update - 1/29 | OB3: Rental Update - 1/30 | OF3: Rental Update - 2/2 | OJ3: Rental Update - 2/3 | ON3: Rental Update - 2/4 | OR3: Rental Update - 2/5 | OV3: Rental Update - 2/6 | OZ3: Rental Update - 2/9 | PD3: Rental Update - 2/10 | PH3: Rental Update - 2/11 | PL3: Rental Update - 2/12 | PP3: Rental Update - 2/13 | PT3: Rental Update - 2/16 | PX3: Rental Update - 2/17 | QB3: Rental Update - 2/18 | QF3: Rental Update - 2/19 | QJ3: Rental Update - 2/20 | QN3: Rental Update - 2/23 | QR3: Rental Update - 2/24 | QV3: Rental Update - 2/25 | QZ3: Rental Update - 2/26 | RD3: Rental Update - 2/27 | RH3: Rental Update - 3/2 | RL3: Rental Update - 3/3 | RP3: Rental Update -3/4 | RT3: Rental Update - 3/5 | RX3: Rental Update - 3/6
A5: Row Labels | B5: Rentals Open | C5: % to all Rentals | D5: Row Labels | E5: Rentals Open | F5: % to all Rentals | G5: Change MTD | H5: Row Labels | I5: Rentals Open | J5: % to all Rentals | K5: Change MTD | L5: Row Labels | M5: Rentals Open | N5: % to all Rentals | O5: Change MTD | P5: Row Labels | Q5: Rentals Open | R5: % to all Rentals | S5: Change MTD | T5: Row Labels | U5: Rentals Open | V5: % to all Rentals | W5: Change MTD | X5: Row Labels | Y5: Rentals Open | Z5: % to all Rentals | AA5: Change MTD | AB5: Row Labels | AC5: Rentals Open | AD5: % to all Rentals | AE5: Change MTD | AF5: Row Labels | AG5: Rentals Open | AH5: % to all Rentals | AI5: Change MTD | AJ5: Row Labels | AK5: Rentals Open | AL5: % to all Rentals | AM5: Change MTD | AN5: Row Labels | AO5: Rentals Open | AP5: % to all Rentals | AQ5: Change MTD | AR5: Row Labels | AS5: Rentals Open | AT5: % to all Rentals | AU5: Change MTD | AV5: Row Labels | AW5: Rentals Open | AX5: % to all Rentals | AY5: Change MTD | AZ5: Row Labels | BA5: Rentals Open | BB5: % to all Rentals | BC5: Change MTD | BD5: Row Labels | BE5: Rentals Open | BF5: % to all Rentals | BG5: Change MTD | BH5: Row Labels | BI5: Rentals Open | BJ5: % to all Rentals | BK5: Change MTD | BL5: Row Labels | BM5: Rentals Open | BN5: % to all Rentals | BO5: Change MTD | BP5: Row Labels | BQ5: Rentals Open | BR5: % to all Rentals | BS5: Change MTD | BT5: Row Labels | BU5: Rentals Open | BV5: % to all Rentals | BW5: Change MTD | BX5: Row Labels | BY5: Rentals Open | BZ5: % to all Rentals | CA5: Change MTD | CB5: Row Labels | CC5: Rentals Open | CD5: % to all Rentals | CE5: Change MTD | CF5: Row Labels | CG5: Rentals Open | CH5: % to all Rentals | CI5: Change MTD | CJ5: Row Labels | CK5: Rentals Open | CL5: % to all Rentals | CM5: Change MTD | CN5: Row Labels | CO5: Rentals Open | CP5: % to all Rentals | CQ5: Change MTD | CR5: Row Labels | CS5: Rentals Open | CT5: % to all Rentals | CU5: Change MTD | CV5: Row Labels | CW5: Rentals Open | CX5: % to all Rentals | CY5: Change MTD | CZ5: Row Labels | DA5: Rentals Open | DB5: % to all Rentals | DC5: Change MTD | DD5: Row Labels | DE5: Rentals Open | DF5: % to all Rentals | DG5: Change MTD | DH5: Row Labels | DI5: Rentals Open | DJ5: % to all Rentals | DK5: Change MTD | DL5: Row Labels | DM5: Rentals Open | DN5: % to all Rentals | DO5: Change MTD | DP5: Row Labels | DQ5: Rentals Open | DR5: % to all Rentals | DS5: Change MTD | DT5: Row Labels | DU5: Rentals Open | DV5: % to all Rentals | DW5: Change MTD | DX5: Row Labels | DY5: Rentals Open | DZ5: % to all Rentals | EA5: Change MTD | EB5: Row Labels | EC5: Rentals Open | ED5: % to all Rentals | EE5: Change MTD | EF5: Row Labels | EG5: Rentals Open | EH5: % to all Rentals | EI5: Change MTD | EJ5: Row Labels | EK5: Rentals Open | EL5: % to all Rentals | EM5: Change MTD | EN5: Row Labels | EO5: Rentals Open | EP5: % to all Rentals | EQ5: Change MTD | ER5: Row Labels | ES5: Rentals Open | ET5: % to all Rentals | EU5: Change MTD | EV5: Row Labels | EW5: Rentals Open | EX5: % to all Rentals | EY5: Change MTD | EZ5: Row Labels | FA5: Rentals Open | FB5: % to all Rentals | FC5: Change MTD | FD5: Row Labels | FE5: Rentals Open | FF5: % to all Rentals | FG5: Change MTD | FH5: Row Labels | FI5: Rentals Open | FJ5: % to all Rentals | FK5: Change MTD | FL5: Row Labels | FM5: Rentals Open | FN5: % to all Rentals | FO5: Change MTD | FP5: Row Labels | FQ5: Rentals Open | FR5: % to all Rentals | FS5: Change MTD | FT5: Row Labels | FU5: Rentals Open | FV5: % to all Rentals | FW5: Change MTD | FX5: Row Labels | FY5: Rentals Open | FZ5: % to all Rentals | GA5: Change MTD | GB5: Row Labels | GC5: Rentals Open | GD5: % to all Rentals | GE5: Change MTD | GF5: Row Labels | GG5: Rentals Open | GH5: % to all Rentals | GI5: Change MTD | GJ5: Row Labels | GK5: Rentals Open | GL5: % to all Rentals | GM5: Change MTD | GN5: Row Labels | GO5: Rentals Open | GP5: % to all Rentals | GQ5: Change MTD | GR5: Row Labels | GS5: Rentals Open | GT5: % to all Rentals | GU5: Change MTD | GV5: Row Labels | GW5: Rentals Open | GX5: % to all Rentals | GY5: Change MTD | GZ5: Row Labels | HA5: Rentals Open | HB5: % to all Rentals | HC5: Change MTD | HD5: Row Labels | HE5: Rentals Open | HF5: % to all Rentals | HG5: Change MTD | HH5: Row Labels | HI5: Rentals Open | HJ5: % to all Rentals | HK5: Change MTD | HL5: Row Labels | HM5: Rentals Open | HN5: % to all Rentals | HO5: Change MTD | HP5: Row Labels | HQ5: Rentals Open | HR5: % to all Rentals | HS5: Change MTD | HT5: Row Labels | HU5: Rentals Open | HV5: % to all Rentals | HW5: Change MTD | HX5: Row Labels | HY5: Rentals Open | HZ5: % to all Rentals | IA5: Change MTD | IB5: Row Labels | IC5: Rentals Open | ID5: % to all Rentals | IE5: Change MTD | IF5: Row Labels | IG5: Rentals Open | IH5: % to all Rentals | II5: Change MTD | IJ5: Row Labels | IK5: Rentals Open | IL5: % to all Rentals | IM5: Change MTD | IN5: Row Labels | IO5: Rentals Open | IP5: % to all Rentals | IQ5: Change MTD | IR5: Row Labels | IS5: Rentals Open | IT5: % to all Rentals | IU5: Change MTD | IV5: Row Labels | IW5: Rentals Open | IX5: % to all Rentals | IY5: Change MTD | IZ5: Row Labels | JA5: Rentals Open | JB5: % to all Rentals | JC5: Change MTD | JD5: Row Labels | JE5: Rentals Open | JF5: % to all Rentals | JG5: Change MTD | JH5: Row Labels | JI5: Rentals Open | JJ5: % to all Rentals | JK5: Change MTD | JL5: Row Labels | JM5: Rentals Open | JN5: % to all Rentals | JO5: Change MTD | JP5: Row Labels | JQ5: Rentals Open | JR5: % to all Rentals | JS5: Change MTD | JT5: Row Labels | JU5: Rentals Open | JV5: % to all Rentals | JW5: Change MTD | JX5: Row Labels | JY5: Rentals Open | JZ5: % to all Rentals | KA5: Change MTD | KB5: Row Labels | KC5: Rentals Open | KD5: % to all Rentals | KE5: Change MTD | KF5: Row Labels | KG5: Rentals Open | KH5: % to all Rentals | KI5: Change MTD | KJ5: Row Labels | KK5: Rentals Open | KL5: % to all Rentals | KM5: Change MTD | KN5: Row Labels | KO5: Rentals Open | KP5: % to all Rentals | KQ5: Change MTD | KR5: Row Labels | KS5: Rentals Open | KT5: % to all Rentals | KU5: Change MTD | KV5: Row Labels | KW5: Rentals Open | KX5: % to all Rentals | KY5: Change MTD | KZ5: Row Labels | LA5: Rentals Open | LB5: % to all Rentals | LC5: Change MTD | LD5: Row Labels | LE5: Rentals Open | LF5: % to all Rentals | LG5: Change MTD | LH5: Row Labels | LI5: Rentals Open | LJ5: % to all Rentals | LK5: Change MTD | LL5: Row Labels | LM5: Rentals Open | LN5: % to all Rentals | LO5: Change MTD | LP5: Row Labels | LQ5: Rentals Open | LR5: % to all Rentals | LS5: Change MTD | LT5: Row Labels | LU5: Rentals Open | LV5: % to all Rentals | LW5: Change MTD | LX5: Row Labels | LY5: Rentals Open | LZ5: % to all Rentals | MA5: Change MTD | MB5: Row Labels | MC5: Rentals Open | MD5: % to all Rentals | ME5: Change MTD | MF5: Row Labels | MG5: Rentals Open | MH5: % to all Rentals | MI5: Change MTD | MJ5: Row Labels | MK5: Rentals Open | ML5: % to all Rentals | MM5: Change MTD | MN5: Row Labels | MO5: Rentals Open | MP5: % to all Rentals | MQ5: Change MTD | MR5: Row Labels | MS5: Rentals Open | MT5: % to all Rentals | MU5: Change MTD | MV5: Row Labels | MW5: Rentals Open | MX5: % to all Rentals | MY5: Change MTD | MZ5: Row Labels | NA5: Rentals Open | NB5: % to all Rentals | NC5: Change MTD | ND5: Row Labels | NE5: Rentals Open | NF5: % to all Rentals | NG5: Change MTD | NH5: Row Labels | NI5: Rentals Open | NJ5: % to all Rentals | NK5: Change MTD | NL5: Row Labels | NM5: Rentals Open | NN5: % to all Rentals | NO5: Change MTD | NP5: Row Labels | NQ5: Rentals Open | NR5: % to all Rentals | NS5: Change MTD | NT5: Row Labels | NU5: Rentals Open | NV5: % to all Rentals | NW5: Change MTD | NX5: Row Labels | NY5: Rentals Open | NZ5: % to all Rentals | OA5: Change MTD | OB5: Row Labels | OC5: Rentals Open | OD5: % to all Rentals | OE5: Change MTD | OF5: Row Labels | OG5: Rentals Open | OH5: % to all Rentals | OI5: Change MTD | OJ5: Row Labels | OK5: Rentals Open | OL5: % to all Rentals | OM5: Change MTD | ON5: Row Labels | OO5: Rentals Open | OP5: % to all Rentals | OQ5: Change MTD | OR5: Row Labels | OS5: Rentals Open | OT5: % to all Rentals | OU5: Change MTD | OV5: Row Labels | OW5: Rentals Open | OX5: % to all Rentals | OY5: Change MTD | OZ5: Row Labels | PA5: Rentals Open | PB5: % to all Rentals | PC5: Change MTD | PD5: Row Labels | PE5: Rentals Open | PF5: % to all Rentals | PG5: Change MTD | PH5: Row Labels | PI5: Rentals Open | PJ5: % to all Rentals | PK5: Change MTD | PL5: Row Labels | PM5: Rentals Open | PN5: % to all Rentals | PO5: Change MTD | PP5: Row Labels | PQ5: Rentals Open | PR5: % to all Rentals | PS5: Change MTD | PT5: Row Labels | PU5: Rentals Open | PV5: % to all Rentals | PW5: Change MTD | PX5: Row Labels | PY5: Rentals Open | PZ5: % to all Rentals | QA5: Change MTD | QB5: Row Labels | QC5: Rentals Open | QD5: % to all Rentals | QE5: Change MTD | QF5: Row Labels | QG5: Rentals Open | QH5: % to all Rentals | QI5: Change MTD | QJ5: Row Labels | QK5: Rentals Open | QL5: % to all Rentals | QM5: Change MTD | QN5: Row Labels | QO5: Rentals Open | QP5: % to all Rentals | QQ5: Change MTD | QR5: Row Labels | QS5: Rentals Open | QT5: % to all Rentals | QU5: Change MTD | QV5: Row Labels | QW5: Rentals Open | QX5: % to all Rentals | QY5: Change MTD | QZ5: Row Labels | RA5: Rentals Open | RB5: % to all Rentals | RC5: Change MTD | RD5: Row Labels | RE5: Rentals Open | RF5: % to all Rentals | RG5: Change MTD | RH5: Row Labels | RI5: Rentals Open | RJ5: % to all Rentals | RK5: Change MTD | RL5: Row Labels | RM5: Rentals Open | RN5: % to all Rentals | RO5: Change MTD | RP5: Row Labels | RQ5: Rentals Open | RR5: % to all Rentals | RS5: Change MTD | RT5: Row Labels | RU5: Rentals Open | RV5: % to all Rentals | RW5: Change MTD | RX5: Row Labels | RY5: Rentals Open | RZ5: % to all Rentals | SA5: Change MTD
A6: 28 plus days | B6: 172 | C6: 0.43107769 | D6: 28 plus days | E6: 217 | F6: 0.51421801 | G6: =E6-$B6 -> 45 | H6: 28 plus days | I6: 217 | J6: 0.51421801 | K6: =I6-$B6 -> 45 | L6: 28 plus days | M6: 214 | N6: 0.54591837 | O6: =M6-$B6 -> 42 | P6: 28 plus days | Q6: 109 | R6: 0.33641975 | S6: =Q6-$B6 -> -63 | T6: 28 plus days | U6: 194 | V6: 0.55428571 | W6: =U6-$B6 -> 22 | X6: 28 plus days | Y6: 196 | Z6: 0.56321839 | AA6: =Y6-$B6 -> 24 | AB6: 28 plus days | AC6: 189 | AD6: 0.54 | AE6: =AC6-$B6 -> 17 | AF6: 28 plus days | AG6: 184 | AH6: 0.52571429 | AI6: =AG6-$B6 -> 12 | AJ6: 28 plus days | AK6: 183 | AL6: 0.52285714 | AM6: =AK6-$B6 -> 11 | AO6: 190 | AP6: 0.55718475 | AQ6: =AO6-$B6 -> 18 | AR6: 28 plus days | AS6: 196 | AT6: 0.56647399 | AU6: =AS6-$B6 -> 24 | AW6: 185 | AX6: 0.56923077 | AY6: =AW6-$B6 -> 13 | BA6: 183 | BB6: 0.56656347 | BC6: =BA6-$B6 -> 11 | BD6: 28 plus days | BE6: 95 | BF6: 0.29503106 | BG6: =BE6-$B6 -> -77 | BH6: 28 plus days | BI6: 83 | BJ6: 0.26948052 | BK6: =BI6-$B6 -> -89 | BL6: 28 plus days | BM6: 88 | BN6: 0.275 | BO6: =BM6-$B6 -> -84 | BP6: 28 plus days | BQ6: 83 | BR6: 0.27302632 | BS6: =BQ6-$B6 -> -89 | BT6: 28 plus days | BU6: 100 | BV6: 0.33112583 | BW6: =BU6-$B6 -> -72 | BX6: 28 plus days | BY6: 86 | BZ6: 0.29553265 | CA6: =BY6-$B6 -> -86 | CB6: 28 plus days | CC6: 126 | CD6: 0.48837209 | CE6: =CC6-$B6 -> -46 | CF6: 28 plus days | CG6: 129 | CH6: 0.48134328 | CI6: =CG6-$B6 -> -43 | CJ6: 28 plus days | CK6: 136 | CL6: 0.49635036 | CM6: =CK6-$B6 -> -36 | CN6: 28 plus days | CO6: 145 | CP6: 0.50699301 | CQ6: =CO6-$B6 -> -27 | CR6: 28 plus days | CS6: 165 | CT6: 0.56701031 | CU6: =CS6-$B6 -> -7 | CV6: 28 plus days | CW6: 196 | CX6: 0.61442006 | CY6: =CW6-$B6 -> 24 | CZ6: 28 plus days | DA6: 196 | DB6: 0.61442006 | DC6: =DA6-$BQ6 -> 113 | DD6: 28 plus days | DE6: 193 | DF6: 0.61858974 | DG6: =DE6-$BQ6 -> 110 | DH6: 28 plus days | DI6: 191 | DJ6: 0.61612903 | DK6: =DI6-$BQ6 -> 108 | DL6: 28 plus days | DM6: 187 | DN6: 0.61513158 | DO6: =DM6-$BQ6 -> 104 | DP6: 28 plus days | DQ6: 189 | DR6: 0.60771704 | DS6: =DQ6-$BQ6 -> 106 | DT6: 28 plus days | DU6: 187 | DV6: 0.59365079 | DW6: =DU6-$BQ6 -> 104 | DX6: 28 plus days | DY6: 184 | DZ6: 0.5974026 | EA6: =DY6-$BQ6 -> 101 | EB6: 28 plus days | EC6: 188 | ED6: 0.61038961 | EE6: =EC6-$BQ6 -> 105 | EF6: 28 plus days | EG6: 175 | EH6: 0.56451613 | EI6: =EG6-$BQ6 -> 92 | EJ6: 28 plus days | EK6: 175 | EL6: 0.55031447 | EM6: =EK6-$BQ6 -> 92 | EN6: 28 plus days | EO6: 175 | EP6: 0.54858934 | EQ6: =EO6-$BQ6 -> 92 | ER6: 28 plus days | ES6: 176 | ET6: 0.56957929 | EU6: =ES6-$EO6 -> 1 | EV6: 28 plus days | EW6: 171 | EX6: 0.57 | EY6: =EW6-$EO6 -> -4 | EZ6: 28 plus days | FA6: 176 | FB6: 0.58085809 | FC6: =FA6-$EO6 -> 1 | FD6: 28 plus days | FE6: 179 | FF6: 0.57928803 | FG6: =FE6-$EO6 -> 4 | FH6: 28 plus days | FI6: 181 | FJ6: 0.58766234 | FK6: =FI6-$EO6 -> 6 | FL6: 28 plus days | FM6: 176 | FN6: 0.58278146 | FO6: =FM6-$EO6 -> 1 | FP6: 28 plus days | FQ6: 175 | FR6: 0.57755776 | FS6: =FQ6-$EO6 -> 0 | FT6: 28 plus days | FU6: 176 | FV6: 0.5751634 | FW6: =FU6-$EO6 -> 1 | FX6: 28 plus days | FY6: 177 | FZ6: 0.58223684 | GA6: =FY6-$EO6 -> 2 | GB6: 28 plus days | GC6: 168 | GD6: 0.52830189 | GE6: =GC6-$EO6 -> -7 | GF6: 28 plus days | GG6: 170 | GH6: 0.53459119 | GI6: =GG6-$EO6 -> -5 | GJ6: 28 plus days | GK6: 168 | GL6: 0.525 | GM6: =GK6-$EO6 -> -7 | GN6: 28 plus days | GO6: 172 | GP6: 0.53250774 | GQ6: =GO6-$EO6 -> -3 | GR6: 28 plus days | GS6: 173 | GT6: 0.54746835 | GU6: =GS6-$EO6 -> -2 | GV6: 28 plus days | GW6: 173 | GX6: 0.56351792 | GY6: =GW6-$EO6 -> -2 | GZ6: 28 plus days | HA6: 179 | HB6: 0.58496732 | HC6: =HA6-$EO6 -> 4 | HD6: 28 plus days | HE6: 178 | HF6: 0.58745875 | HG6: =HE6-$EO6 -> 3 | HH6: 28 plus days | HI6: 179 | HJ6: 0.58496732 | HK6: =HI6-$HE6 -> 1 | HL6: 28 plus days | HM6: 185 | HN6: 0.56402439 | HO6: =HM6-$HE6 -> 7 | HP6: 28 plus days | HQ6: 185 | HR6: 0.55555556 | HS6: =HQ6-$HE6 -> 7 | HT6: 28 plus days | HU6: 190 | HV6: 0.55393586 | HW6: =HU6-$HE6 -> 12 | HX6: 28 plus days | HY6: 189 | HZ6: 0.5494186 | IA6: =HY6-$HE6 -> 11 | IB6: 28 plus days | IC6: 186 | ID6: 0.55192878 | IE6: =IC6-$HE6 -> 8 | IF6: 28 plus days | IG6: 181 | IH6: 0.54848485 | II6: =IG6-$HE6 -> 3 | IJ6: 28 plus days | IK6: 181 | IL6: 0.5339233 | IM6: =IK6-$HE6 -> 3 | IN6: 28 plus days | IO6: 183 | IP6: 0.53508772 | IQ6: =IO6-$HE6 -> 5 | IR6: 28 plus days | IS6: 187 | IT6: 0.53581662 | IU6: =IS6-$HE6 -> 9 | IV6: 28 plus days | IW6: 184 | IX6: 0.5508982 | IY6: =IW6-$HE6 -> 6 | IZ6: 28 plus days | JA6: 187 | JB6: 0.54202899 | JC6: =JA6-$HE6 -> 9 | JD6: 28 plus days | JE6: 193 | JF6: 0.56764706 | JG6: =JE6-$HE6 -> 15 | JH6: 28 plus days | JI6: 199 | JJ6: 0.584 | JK6: =JI6-$HE6 -> 21 | JL6: 28 plus days | JM6: 194 | JN6: 0.57227139 | JO6: =JM6-$HE6 -> 16 | JP6: 28 plus days | JQ6: 191 | JR6: 0.57014925 | JS6: =JQ6-$HE6 -> 13 | JT6: 28 plus days | JU6: 188 | JV6: 0.56626506 | JW6: =JU6-$HE6 -> 10 | JX6: 28 plus days | JY6: 188 | JZ6: 0.56626506 | KA6: =JY6-$HE6 -> 10 | KB6: 28 plus days | KC6: 188 | KD6: 0.56626506 | KE6: =KC6-$HE6 -> 10 | KF6: 28 plus days | KG6: 194 | KH6: 0.59876543 | KI6: =KG6-$HE6 -> 16 | KJ6: 28 plus days | KK6: 199 | KL6: 0.61042945 | KM6: =KK6-$HE6 -> 21 | KN6: 28 plus days | KO6: 206 | KP6: 0.62424242 | KQ6: =KO6-$HE6 -> 28 | KR6: 28 plus days | KS6: 206 | KT6: 0.62804878 | KU6: =KS6-$HE6 -> 28 | KV6: 28 plus days | KW6: 206 | KX6: 0.62804878 | KY6: =KW6-$HE6 -> 28 | KZ6: 28 plus days | LA6: 213 | LB6: 0.64156627 | LC6: =LA6-$HE6 -> 35 | LD6: 28 plus days | LE6: 211 | LF6: 0.64329268 | LG6: =LE6-$LA6 -> -2 | LH6: 28 plus days | LI6: 210 | LJ6: 0.63444109 | LK6: =LI6-$LA6 -> -3 | LL6: 28 plus days | LM6: 209 | LN6: 0.6183432 | LO6: =LM6-$LA6 -> -4 | LP6: 28 plus days | LQ6: 214 | LR6: 0.63126844 | LS6: =LQ6-$LA6 -> 1 | LT6: 28 plus days | LU6: 211 | LV6: 0.61337209 | LW6: =LU6-$LA6 -> -2 | LX6: 28 plus days | LY6: 210 | LZ6: 0.61403509 | MA6: =LY6-$LA6 -> -3 | MB6: 28 plus days | MC6: 200 | MD6: 0.5899705 | ME6: =MC6-$LA6 -> -13 | MF6: 28 plus days | MG6: 200 | MH6: 0.58651026 | MI6: =MG6-$LA6 -> -13 | MJ6: 28 plus days | MK6: 200 | ML6: 0.5952381 | MM6: =MK6-$LA6 -> -13 | MN6: 28 plus days | MO6: 205 | MP6: 0.60650888 | MQ6: =MO6-$LA6 -> -8 | MR6: 28 plus days | MS6: 209 | MT6: 0.62202381 | MU6: =MS6-$LA6 -> -4 | MV6: 28 plus days | MW6: 206 | MX6: 0.60766962 | MY6: =MW6-$LA6 -> -7 | MZ6: 28 plus days | NA6: 204 | NB6: 0.6 | NC6: =NA6-$LA6 -> -9 | ND6: 28 plus days | NE6: 201 | NF6: 0.59467456 | NG6: =NE6-$LA6 -> -12 | NH6: 28 plus days | NI6: 193 | NJ6: 0.58484848 | NK6: =NI6-$LA6 -> -20 | NL6: 28 plus days | NM6: 201 | NN6: 0.61846154 | NO6: =NM6-$LA6 -> -12 | NP6: 28 plus days | NQ6: 201 | NR6: 0.6036036 | NS6: =NQ6-$LA6 -> -12 | NT6: 28 plus days | NU6: 200 | NV6: 0.58139535 | NW6: =NU6-$LA6 -> -13 | NX6: 28 plus days | NY6: 196 | NZ6: 0.5648415 | OA6: =NY6-$LA6 -> -17 | OB6: 28 plus days | OC6: 196 | OD6: 0.58333333 | OE6: =OC6-$LA6 -> -17 | OF6: 28 plus days | OG6: 195 | OH6: 0.58383234 | OI6: =OG6-$OC6 -> -1 | OJ6: 28 plus days | OK6: 196 | OL6: 0.57478006 | OM6: =OK6-$OC6 -> 0 | ON6: 28 plus days | OO6: 198 | OP6: 0.58579882 | OQ6: =OO6-$OC6 -> 2 | OR6: 28 plus days | OS6: 203 | OT6: 0.59705882 | OU6: =OS6-$OC6 -> 7 | OV6: 28 plus days | OW6: 201 | OX6: 0.60179641 | OY6: =OW6-$OC6 -> 5 | OZ6: 28 plus days | PA6: 204 | PB6: 0.61077844 | PC6: =PA6-$OC6 -> 8 | PD6: 28 plus days | PE6: 204 | PF6: 0.60176991 | PG6: =PE6-$OC6 -> 8 | PH6: 28 plus days | PI6: 199 | PJ6: 0.5887574 | PK6: =PI6-$OC6 -> 3 | PL6: 28 plus days | PM6: 203 | PN6: 0.60597015 | PO6: =PM6-$OC6 -> 7 | PP6: 28 plus days | PQ6: 207 | PR6: 0.61424332 | PS6: =PQ6-$OC6 -> 11 | PT6: 28 plus days | PU6: 205 | PV6: 0.625 | PW6: =PU6-$OC6 -> 9 | PX6: 28 plus days | PY6: 208 | PZ6: 0.62650602 | QA6: =PY6-$OC6 -> 12 | QB6: 28 plus days | QC6: 199 | QD6: 0.63174603 | QE6: =QC6-$OC6 -> 3 | QF6: 28 plus days | QG6: 198 | QH6: 0.64705882 | QI6: =QG6-$OC6 -> 2 | QJ6: 28 plus days | QK6: 191 | QL6: 0.65635739 | QM6: =QK6-$OC6 -> -5 | QN6: 28 plus days | QO6: 187 | QP6: 0.67266187 | QQ6: =QO6-$OC6 -> -9 | QR6: 28 plus days | QS6: 175 | QT6: 0.67307692 | QU6: =QS6-$OC6 -> -21 | QV6: 28 plus days | QW6: 200 | QX6: 0.59171598 | QY6: =QW6-$OC6 -> 4 | QZ6: 28 plus days | RA6: 198 | RB6: 0.59104478 | RC6: =RA6-$OC6 -> 2 | RD6: 28 plus days | RE6: 193 | RF6: 0.5659824 | RG6: =RE6-$OC6 -> -3 | RH6: 28 plus days | RI6: 192 | RJ6: 0.58006042 | RK6: =RI6-$RE6 -> -1 | RL6: 28 plus days | RM6: 192 | RN6: 0.58006042 | RO6: =RM6-$RE6 -> -1 | RP6: 28 plus days | RQ6: 192 | RR6: 0.57657658 | RS6: =RQ6-$RE6 -> -1 | RT6: 28 plus days | RU6: 192 | RV6: 0.57831325 | RW6: =RU6-$RE6 -> -1 | RX6: 28 plus days | SA6: =RY6-$RE6 -> -193
A7: 21 plus days | B7: 55 | C7: 0.13784461 | D7: 21 plus days | E7: 55 | F7: 0.13033175 | G7: =E7-$B7 -> 0 | H7: 21 plus days | I7: 55 | J7: 0.13033175 | K7: =I7-$B7 -> 0 | L7: 21 plus days | M7: 27 | N7: 0.068877551 | O7: =M7-$B7 -> -28 | P7: 21 plus days | Q7: 39 | R7: 0.12037037 | S7: =Q7-$B7 -> -16 | T7: 21 plus days | U7: 42 | V7: 0.12 | W7: =U7-$B7 -> -13 | X7: 21 plus days | Y7: 38 | Z7: 0.1091954 | AA7: =Y7-$B7 -> -17 | AB7: 21 plus days | AC7: 33 | AD7: 0.094285714 | AE7: =AC7-$B7 -> -22 | AF7: 21 plus days | AG7: 36 | AH7: 0.10285714 | AI7: =AG7-$B7 -> -19 | AJ7: 21 plus days | AK7: 37 | AL7: 0.10571429 | AM7: =AK7-$B7 -> -18 | AO7: 27 | AP7: 0.079178886 | AQ7: =AO7-$B7 -> -28 | AR7: 21 plus days | AS7: 19 | AT7: 0.054913295 | AU7: =AS7-$B7 -> -36 | AW7: 18 | AX7: 0.055384615 | AY7: =AW7-$B7 -> -37 | BA7: 17 | BB7: 0.052631579 | BC7: =BA7-$B7 -> -38 | BD7: 21 plus days | BE7: 52 | BF7: 0.16149068 | BG7: =BE7-$B7 -> -3 | BH7: 21 plus days | BI7: 69 | BJ7: 0.22402597 | BK7: =BI7-$B7 -> 14 | BL7: 21 plus days | BM7: 70 | BN7: 0.21875 | BO7: =BM7-$B7 -> 15 | BP7: 21 plus days | BQ7: 61 | BR7: 0.20065789 | BS7: =BQ7-$B7 -> 6 | BT7: 21 plus days | BU7: 65 | BV7: 0.21523179 | BW7: =BU7-$B7 -> 10 | BX7: 21 plus days | BY7: 61 | BZ7: 0.20962199 | CA7: =BY7-$B7 -> 6 | CB7: 21 plus days | CC7: 27 | CD7: 0.10465116 | CE7: =CC7-$B7 -> -28 | CF7: 21 plus days | CG7: 21 | CH7: 0.078358209 | CI7: =CG7-$B7 -> -34 | CJ7: 21 plus days | CK7: 22 | CL7: 0.080291971 | CM7: =CK7-$B7 -> -33 | CN7: 21 plus days | CO7: 23 | CP7: 0.08041958 | CQ7: =CO7-$B7 -> -32 | CR7: 21 plus days | CS7: 19 | CT7: 0.065292096 | CU7: =CS7-$B7 -> -36 | CV7: 21 plus days | CW7: 13 | CX7: 0.040752351 | CY7: =CW7-$B7 -> -42 | CZ7: 21 plus days | DA7: 11 | DB7: 0.034482759 | DC7: =DA7-$BQ7 -> -50 | DD7: 21 plus days | DE7: 13 | DF7: 0.041666667 | DG7: =DE7-$BQ7 -> -48 | DH7: 21 plus days | DI7: 19 | DJ7: 0.061290323 | DK7: =DI7-$BQ7 -> -42 | DL7: 21 plus days | DM7: 19 | DN7: 0.0625 | DO7: =DM7-$BQ7 -> -42 | DP7: 21 plus days | DQ7: 18 | DR7: 0.057877814 | DS7: =DQ7-$BQ7 -> -43 | DT7: 21 plus days | DU7: 18 | DV7: 0.057142857 | DW7: =DU7-$BQ7 -> -43 | DX7: 21 plus days | DY7: 20 | DZ7: 0.064935065 | EA7: =DY7-$BQ7 -> -41 | EB7: 21 plus days | EC7: 16 | ED7: 0.051948052 | EE7: =EC7-$BQ7 -> -45 | EF7: 21 plus days | EG7: 19 | EH7: 0.061290323 | EI7: =EG7-$BQ7 -> -42 | EJ7: 21 plus days | EK7: 22 | EL7: 0.06918239 | EM7: =EK7-$BQ7 -> -39 | EN7: 21 plus days | EO7: 24 | EP7: 0.07523511 | EQ7: =EO7-$BQ7 -> -37 | ER7: 21 plus days | ES7: 26 | ET7: 0.084142395 | EU7: =ES7-$EO7 -> 2 | EV7: 21 plus days | EW7: 25 | EX7: 0.083333333 | EY7: =EW7-$EO7 -> 1 | EZ7: 21 plus days | FA7: 21 | FB7: 0.069306931 | FC7: =FA7-$EO7 -> -3 | FD7: 21 plus days | FE7: 25 | FF7: 0.080906149 | FG7: =FE7-$EO7 -> 1 | FH7: 21 plus days | FI7: 20 | FJ7: 0.064935065 | FK7: =FI7-$EO7 -> -4 | FL7: 21 plus days | FM7: 17 | FN7: 0.056291391 | FO7: =FM7-$EO7 -> -7 | FP7: 21 plus days | FQ7: 18 | FR7: 0.059405941 | FS7: =FQ7-$EO7 -> -6 | FT7: 21 plus days | FU7: 17 | FV7: 0.055555556 | FW7: =FU7-$EO7 -> -7 | FX7: 21 plus days | FY7: 19 | FZ7: 0.0625 | GA7: =FY7-$EO7 -> -5 | GB7: 21 plus days | GC7: 24 | GD7: 0.075471698 | GE7: =GC7-$EO7 -> 0 | GF7: 21 plus days | GG7: 29 | GH7: 0.091194969 | GI7: =GG7-$EO7 -> 5 | GJ7: 21 plus days | GK7: 34 | GL7: 0.10625 | GM7: =GK7-$EO7 -> 10 | GN7: 21 plus days | GO7: 34 | GP7: 0.10526316 | GQ7: =GO7-$EO7 -> 10 | GR7: 21 plus days | GS7: 28 | GT7: 0.088607595 | GU7: =GS7-$EO7 -> 4 | GV7: 21 plus days | GW7: 26 | GX7: 0.084690554 | GY7: =GW7-$EO7 -> 2 | GZ7: 21 plus days | HA7: 21 | HB7: 0.068627451 | HC7: =HA7-$EO7 -> -3 | HD7: 21 plus days | HE7: 18 | HF7: 0.059405941 | HG7: =HE7-$EO7 -> -6 | HH7: 21 plus days | HI7: 22 | HJ7: 0.071895425 | HK7: =HI7-$HE7 -> 4 | HL7: 21 plus days | HM7: 19 | HN7: 0.057926829 | HO7: =HM7-$HE7 -> 1 | HP7: 21 plus days | HQ7: 18 | HR7: 0.054054054 | HS7: =HQ7-$HE7 -> 0 | HT7: 21 plus days | HU7: 20 | HV7: 0.058309038 | HW7: =HU7-$HE7 -> 2 | HX7: 21 plus days | HY7: 25 | HZ7: 0.072674419 | IA7: =HY7-$HE7 -> 7 | IB7: 21 plus days | IC7: 26 | ID7: 0.077151335 | IE7: =IC7-$HE7 -> 8 | IF7: 21 plus days | IG7: 29 | IH7: 0.087878788 | II7: =IG7-$HE7 -> 11 | IJ7: 21 plus days | IK7: 36 | IL7: 0.10619469 | IM7: =IK7-$HE7 -> 18 | IN7: 21 plus days | IO7: 35 | IP7: 0.10233918 | IQ7: =IO7-$HE7 -> 17 | IR7: 21 plus days | IS7: 33 | IT7: 0.094555874 | IU7: =IS7-$HE7 -> 15 | IV7: 21 plus days | IW7: 26 | IX7: 0.077844311 | IY7: =IW7-$HE7 -> 8 | IZ7: 21 plus days | JA7: 24 | JB7: 0.069565217 | JC7: =JA7-$HE7 -> 6 | JD7: 21 plus days | JE7: 21 | JF7: 0.061764706 | JG7: =JE7-$HE7 -> 3 | JH7: 21 plus days | JI7: 17 | JJ7: 0.05 | JK7: =JI7-$HE7 -> -1 | JL7: 21 plus days | JM7: 16 | JN7: 0.04719764 | JO7: =JM7-$HE7 -> -2 | JP7: 21 plus days | JQ7: 25 | JR7: 0.074626866 | JS7: =JQ7-$HE7 -> 7 | JT7: 21 plus days | JU7: 28 | JV7: 0.084337349 | JW7: =JU7-$HE7 -> 10 | JX7: 21 plus days | JY7: 28 | JZ7: 0.084337349 | KA7: =JY7-$HE7 -> 10 | KB7: 21 plus days | KC7: 28 | KD7: 0.084337349 | KE7: =KC7-$HE7 -> 10 | KF7: 21 plus days | KG7: 28 | KH7: 0.086419753 | KI7: =KG7-$HE7 -> 10 | KJ7: 21 plus days | KK7: 23 | KL7: 0.070552147 | KM7: =KK7-$HE7 -> 5 | KN7: 21 plus days | KO7: 19 | KP7: 0.057575758 | KQ7: =KO7-$HE7 -> 1 | KR7: 21 plus days | KS7: 19 | KT7: 0.057926829 | KU7: =KS7-$HE7 -> 1 | KV7: 21 plus days | KW7: 19 | KX7: 0.057926829 | KY7: =KW7-$HE7 -> 1 | KZ7: 21 plus days | LA7: 25 | LB7: 0.075301205 | LC7: =LA7-$HE7 -> 7 | LD7: 21 plus days | LE7: 30 | LF7: 0.091463415 | LG7: =LE7-$LA7 -> 5 | LH7: 21 plus days | LI7: 30 | LJ7: 0.090634441 | LK7: =LI7-$LA7 -> 5 | LL7: 21 plus days | LM7: 34 | LN7: 0.10059172 | LO7: =LM7-$LA7 -> 9 | LP7: 21 plus days | LQ7: 27 | LR7: 0.079646018 | LS7: =LQ7-$LA7 -> 2 | LT7: 21 plus days | LU7: 30 | LV7: 0.087209302 | LW7: =LU7-$LA7 -> 5 | LX7: 21 plus days | LY7: 30 | LZ7: 0.087719298 | MA7: =LY7-$LA7 -> 5 | MB7: 21 plus days | MC7: 28 | MD7: 0.08259587 | ME7: =MC7-$LA7 -> 3 | MF7: 21 plus days | MG7: 21 | MH7: 0.061583578 | MI7: =MG7-$LA7 -> -4 | MJ7: 21 plus days | MK7: 16 | ML7: 0.047619048 | MM7: =MK7-$LA7 -> -9 | MN7: 21 plus days | MO7: 15 | MP7: 0.044378698 | MQ7: =MO7-$LA7 -> -10 | MR7: 21 plus days | MS7: 18 | MT7: 0.053571429 | MU7: =MS7-$LA7 -> -7 | MV7: 21 plus days | MW7: 18 | MX7: 0.053097345 | MY7: =MW7-$LA7 -> -7 | MZ7: 21 plus days | NA7: 17 | NB7: 0.05 | NC7: =NA7-$LA7 -> -8 | ND7: 21 plus days | NE7: 15 | NF7: 0.044378698 | NG7: =NE7-$LA7 -> -10 | NH7: 21 plus days | NI7: 18 | NJ7: 0.054545455 | NK7: =NI7-$LA7 -> -7 | NL7: 21 plus days | NM7: 28 | NN7: 0.086153846 | NO7: =NM7-$LA7 -> 3 | NP7: 21 plus days | NQ7: 27 | NR7: 0.081081081 | NS7: =NQ7-$LA7 -> 2 | NT7: 21 plus days | NU7: 25 | NV7: 0.072674419 | NW7: =NU7-$LA7 -> 0 | NX7: 21 plus days | NY7: 31 | NZ7: 0.089337176 | OA7: =NY7-$LA7 -> 6 | OB7: 21 plus days | OC7: 28 | OD7: 0.083333333 | OE7: =OC7-$LA7 -> 3 | OF7: 21 plus days | OG7: 30 | OH7: 0.089820359 | OI7: =OG7-$OC7 -> 2 | OJ7: 21 plus days | OK7: 27 | OL7: 0.079178886 | OM7: =OK7-$OC7 -> -1 | ON7: 21 plus days | OO7: 22 | OP7: 0.065088757 | OQ7: =OO7-$OC7 -> -6 | OR7: 21 plus days | OS7: 20 | OT7: 0.058823529 | OU7: =OS7-$OC7 -> -8 | OV7: 21 plus days | OW7: 23 | OX7: 0.068862275 | OY7: =OW7-$OC7 -> -5 | OZ7: 21 plus days | PA7: 23 | PB7: 0.068862275 | PC7: =PA7-$OC7 -> -5 | PD7: 21 plus days | PE7: 22 | PF7: 0.064896755 | PG7: =PE7-$OC7 -> -6 | PH7: 21 plus days | PI7: 28 | PJ7: 0.082840237 | PK7: =PI7-$OC7 -> 0 | PL7: 21 plus days | PM7: 28 | PN7: 0.08358209 | PO7: =PM7-$OC7 -> 0 | PP7: 21 plus days | PQ7: 23 | PR7: 0.068249258 | PS7: =PQ7-$OC7 -> -5 | PT7: 21 plus days | PU7: 22 | PV7: 0.067073171 | PW7: =PU7-$OC7 -> -6 | PX7: 21 plus days | PY7: 22 | PZ7: 0.06626506 | QA7: =PY7-$OC7 -> -6 | QB7: 21 plus days | QC7: 20 | QD7: 0.063492063 | QE7: =QC7-$OC7 -> -8 | QF7: 21 plus days | QG7: 18 | QH7: 0.058823529 | QI7: =QG7-$OC7 -> -10 | QJ7: 21 plus days | QK7: 19 | QL7: 0.065292096 | QM7: =QK7-$OC7 -> -9 | QN7: 21 plus days | QO7: 20 | QP7: 0.071942446 | QQ7: =QO7-$OC7 -> -8 | QR7: 21 plus days | QS7: 18 | QT7: 0.069230769 | QU7: =QS7-$OC7 -> -10 | QV7: 21 plus days | QW7: 19 | QX7: 0.056213018 | QY7: =QW7-$OC7 -> -9 | QZ7: 21 plus days | RA7: 22 | RB7: 0.065671642 | RC7: =RA7-$OC7 -> -6 | RD7: 21 plus days | RE7: 22 | RF7: 0.064516129 | RG7: =RE7-$OC7 -> -6 | RH7: 21 plus days | RI7: 25 | RJ7: 0.075528701 | RK7: =RI7-$RE7 -> 3 | RL7: 21 plus days | RM7: 21 | RN7: 0.063444109 | RO7: =RM7-$RE7 -> -1 | RP7: 21 plus days | RQ7: 22 | RR7: 0.066066066 | RS7: =RQ7-$RE7 -> 0 | RT7: 21 plus days | RU7: 22 | RV7: 0.06626506 | RW7: =RU7-$RE7 -> 0 | RX7: 21 plus days | SA7: =RY7-$RE7 -> -22
A8: 14 plus days | B8: 40 | C8: 0.10025063 | D8: 14 plus days | E8: 46 | F8: 0.10900474 | G8: =E8-$B8 -> 6 | H8: 14 plus days | I8: 46 | J8: 0.10900474 | K8: =I8-$B8 -> 6 | L8: 14 plus days | M8: 56 | N8: 0.14285714 | O8: =M8-$B8 -> 16 | P8: 14 plus days | Q8: 37 | R8: 0.11419753 | S8: =Q8-$B8 -> -3 | T8: 14 plus days | U8: 27 | V8: 0.077142857 | W8: =U8-$B8 -> -13 | X8: 14 plus days | Y8: 30 | Z8: 0.086206897 | AA8: =Y8-$B8 -> -10 | AB8: 14 plus days | AC8: 28 | AD8: 0.08 | AE8: =AC8-$B8 -> -12 | AF8: 14 plus days | AG8: 29 | AH8: 0.082857143 | AI8: =AG8-$B8 -> -11 | AJ8: 14 plus days | AK8: 29 | AL8: 0.082857143 | AM8: =AK8-$B8 -> -11 | AO8: 38 | AP8: 0.11143695 | AQ8: =AO8-$B8 -> -2 | AR8: 14 plus days | AS8: 43 | AT8: 0.12427746 | AU8: =AS8-$B8 -> 3 | AW8: 48 | AX8: 0.14769231 | AY8: =AW8-$B8 -> 8 | BA8: 46 | BB8: 0.14241486 | BC8: =BA8-$B8 -> 6 | BD8: 14 plus days | BE8: 71 | BF8: 0.22049689 | BG8: =BE8-$B8 -> 31 | BH8: 14 plus days | BI8: 63 | BJ8: 0.20454545 | BK8: =BI8-$B8 -> 23 | BL8: 14 plus days | BM8: 62 | BN8: 0.19375 | BO8: =BM8-$B8 -> 22 | BP8: 14 plus days | BQ8: 55 | BR8: 0.18092105 | BS8: =BQ8-$B8 -> 15 | BT8: 14 plus days | BU8: 52 | BV8: 0.17218543 | BW8: =BU8-$B8 -> 12 | BX8: 14 plus days | BY8: 49 | BZ8: 0.16838488 | CA8: =BY8-$B8 -> 9 | CB8: 14 plus days | CC8: 27 | CD8: 0.10465116 | CE8: =CC8-$B8 -> -13 | CF8: 14 plus days | CG8: 34 | CH8: 0.12686567 | CI8: =CG8-$B8 -> -6 | CJ8: 14 plus days | CK8: 38 | CL8: 0.13868613 | CM8: =CK8-$B8 -> -2 | CN8: 14 plus days | CO8: 42 | CP8: 0.14685315 | CQ8: =CO8-$B8 -> 2 | CR8: 14 plus days | CS8: 28 | CT8: 0.096219931 | CU8: =CS8-$B8 -> -12 | CV8: 14 plus days | CW8: 21 | CX8: 0.065830721 | CY8: =CW8-$B8 -> -19 | CZ8: 14 plus days | DA8: 23 | DB8: 0.072100313 | DC8: =DA8-$BQ8 -> -32 | DD8: 14 plus days | DE8: 24 | DF8: 0.076923077 | DG8: =DE8-$BQ8 -> -31 | DH8: 14 plus days | DI8: 21 | DJ8: 0.067741935 | DK8: =DI8-$BQ8 -> -34 | DL8: 14 plus days | DM8: 23 | DN8: 0.075657895 | DO8: =DM8-$BQ8 -> -32 | DP8: 14 plus days | DQ8: 32 | DR8: 0.10289389 | DS8: =DQ8-$BQ8 -> -23 | DT8: 14 plus days | DU8: 35 | DV8: 0.11111111 | DW8: =DU8-$BQ8 -> -20 | DX8: 14 plus days | DY8: 38 | DZ8: 0.12337662 | EA8: =DY8-$BQ8 -> -17 | EB8: 14 plus days | EC8: 35 | ED8: 0.11363636 | EE8: =EC8-$BQ8 -> -20 | EF8: 14 plus days | EG8: 29 | EH8: 0.093548387 | EI8: =EG8-$BQ8 -> -26 | EJ8: 14 plus days | EK8: 30 | EL8: 0.094339623 | EM8: =EK8-$BQ8 -> -25 | EN8: 14 plus days | EO8: 26 | EP8: 0.081504702 | EQ8: =EO8-$BQ8 -> -29 | ER8: 14 plus days | ES8: 26 | ET8: 0.084142395 | EU8: =ES8-$EO8 -> 0 | EV8: 14 plus days | EW8: 23 | EX8: 0.076666667 | EY8: =EW8-$EO8 -> -3 | EZ8: 14 plus days | FA8: 24 | FB8: 0.079207921 | FC8: =FA8-$EO8 -> -2 | FD8: 14 plus days | FE8: 23 | FF8: 0.074433657 | FG8: =FE8-$EO8 -> -3 | FH8: 14 plus days | FI8: 31 | FJ8: 0.10064935 | FK8: =FI8-$EO8 -> 5 | FL8: 14 plus days | FM8: 32 | FN8: 0.10596026 | FO8: =FM8-$EO8 -> 6 | FP8: 14 plus days | FQ8: 32 | FR8: 0.10561056 | FS8: =FQ8-$EO8 -> 6 | FT8: 14 plus days | FU8: 37 | FV8: 0.12091503 | FW8: =FU8-$EO8 -> 11 | FX8: 14 plus days | FY8: 35 | FZ8: 0.11513158 | GA8: =FY8-$EO8 -> 9 | GB8: 14 plus days | GC8: 33 | GD8: 0.10377358 | GE8: =GC8-$EO8 -> 7 | GF8: 14 plus days | GG8: 31 | GH8: 0.097484277 | GI8: =GG8-$EO8 -> 5 | GJ8: 14 plus days | GK8: 26 | GL8: 0.08125 | GM8: =GK8-$EO8 -> 0 | GN8: 14 plus days | GO8: 25 | GP8: 0.077399381 | GQ8: =GO8-$EO8 -> -1 | GR8: 14 plus days | GS8: 26 | GT8: 0.082278481 | GU8: =GS8-$EO8 -> 0 | GV8: 14 plus days | GW8: 26 | GX8: 0.084690554 | GY8: =GW8-$EO8 -> 0 | GZ8: 14 plus days | HA8: 23 | HB8: 0.075163399 | HC8: =HA8-$EO8 -> -3 | HD8: 14 plus days | HE8: 21 | HF8: 0.069306931 | HG8: =HE8-$EO8 -> -5 | HH8: 14 plus days | HI8: 31 | HJ8: 0.10130719 | HK8: =HI8-$HE8 -> 10 | HL8: 14 plus days | HM8: 38 | HN8: 0.11585366 | HO8: =HM8-$HE8 -> 17 | HP8: 14 plus days | HQ8: 41 | HR8: 0.12312312 | HS8: =HQ8-$HE8 -> 20 | HT8: 14 plus days | HU8: 38 | HV8: 0.11078717 | HW8: =HU8-$HE8 -> 17 | HX8: 14 plus days | HY8: 35 | HZ8: 0.10174419 | IA8: =HY8-$HE8 -> 14 | IB8: 14 plus days | IC8: 33 | ID8: 0.097922849 | IE8: =IC8-$HE8 -> 12 | IF8: 14 plus days | IG8: 31 | IH8: 0.093939394 | II8: =IG8-$HE8 -> 10 | IJ8: 14 plus days | IK8: 25 | IL8: 0.073746313 | IM8: =IK8-$HE8 -> 4 | IN8: 14 plus days | IO8: 20 | IP8: 0.058479532 | IQ8: =IO8-$HE8 -> -1 | IR8: 14 plus days | IS8: 19 | IT8: 0.054441261 | IU8: =IS8-$HE8 -> -2 | IV8: 14 plus days | IW8: 33 | IX8: 0.098802395 | IY8: =IW8-$HE8 -> 12 | IZ8: 14 plus days | JA8: 36 | JB8: 0.10434783 | JC8: =JA8-$HE8 -> 15 | JD8: 14 plus days | JE8: 34 | JF8: 0.1 | JG8: =JE8-$HE8 -> 13 | JH8: 14 plus days | JI8: 41 | JJ8: 0.12 | JK8: =JI8-$HE8 -> 20 | JL8: 14 plus days | JM8: 38 | JN8: 0.1120944 | JO8: =JM8-$HE8 -> 17 | JP8: 14 plus days | JQ8: 30 | JR8: 0.089552239 | JS8: =JQ8-$HE8 -> 9 | JT8: 14 plus days | JU8: 23 | JV8: 0.069277108 | JW8: =JU8-$HE8 -> 2 | JX8: 14 plus days | JY8: 23 | JZ8: 0.069277108 | KA8: =JY8-$HE8 -> 2 | KB8: 14 plus days | KC8: 23 | KD8: 0.069277108 | KE8: =KC8-$HE8 -> 2 | KF8: 14 plus days | KG8: 33 | KH8: 0.10185185 | KI8: =KG8-$HE8 -> 12 | KJ8: 14 plus days | KK8: 39 | KL8: 0.1196319 | KM8: =KK8-$HE8 -> 18 | KN8: 14 plus days | KO8: 37 | KP8: 0.11212121 | KQ8: =KO8-$HE8 -> 16 | KR8: 14 plus days | KS8: 38 | KT8: 0.11585366 | KU8: =KS8-$HE8 -> 17 | KV8: 14 plus days | KW8: 38 | KX8: 0.11585366 | KY8: =KW8-$HE8 -> 17 | KZ8: 14 plus days | LA8: 34 | LB8: 0.10240964 | LC8: =LA8-$HE8 -> 13 | LD8: 14 plus days | LE8: 34 | LF8: 0.10365854 | LG8: =LE8-$LA8 -> 0 | LH8: 14 plus days | LI8: 32 | LJ8: 0.096676737 | LK8: =LI8-$LA8 -> -2 | LL8: 14 plus days | LM8: 26 | LN8: 0.076923077 | LO8: =LM8-$LA8 -> -8 | LP8: 14 plus days | LQ8: 21 | LR8: 0.061946903 | LS8: =LQ8-$LA8 -> -13 | LT8: 14 plus days | LU8: 20 | LV8: 0.058139535 | LW8: =LU8-$LA8 -> -14 | LX8: 14 plus days | LY8: 17 | LZ8: 0.049707602 | MA8: =LY8-$LA8 -> -17 | MB8: 14 plus days | MC8: 19 | MD8: 0.056047198 | ME8: =MC8-$LA8 -> -15 | MF8: 14 plus days | MG8: 19 | MH8: 0.055718475 | MI8: =MG8-$LA8 -> -15 | MJ8: 14 plus days | MK8: 19 | ML8: 0.056547619 | MM8: =MK8-$LA8 -> -15 | MN8: 14 plus days | MO8: 22 | MP8: 0.065088757 | MQ8: =MO8-$LA8 -> -12 | MR8: 14 plus days | MS8: 29 | MT8: 0.086309524 | MU8: =MS8-$LA8 -> -5 | MV8: 14 plus days | MW8: 27 | MX8: 0.079646018 | MY8: =MW8-$LA8 -> -7 | MZ8: 14 plus days | NA8: 31 | NB8: 0.091176471 | NC8: =NA8-$LA8 -> -3 | ND8: 14 plus days | NE8: 37 | NF8: 0.10946746 | NG8: =NE8-$LA8 -> 3 | NH8: 14 plus days | NI8: 34 | NJ8: 0.1030303 | NK8: =NI8-$LA8 -> 0 | NL8: 14 plus days | NM8: 32 | NN8: 0.098461538 | NO8: =NM8-$LA8 -> -2 | NP8: 14 plus days | NQ8: 32 | NR8: 0.096096096 | NS8: =NQ8-$LA8 -> -2 | NT8: 14 plus days | NU8: 30 | NV8: 0.087209302 | NW8: =NU8-$LA8 -> -4 | NX8: 14 plus days | NY8: 30 | NZ8: 0.086455331 | OA8: =NY8-$LA8 -> -4 | OB8: 14 plus days | OC8: 28 | OD8: 0.083333333 | OE8: =OC8-$LA8 -> -6 | OF8: 14 plus days | OG8: 27 | OH8: 0.080838323 | OI8: =OG8-$OC8 -> -1 | OJ8: 14 plus days | OK8: 27 | OL8: 0.079178886 | OM8: =OK8-$OC8 -> -1 | ON8: 14 plus days | OO8: 31 | OP8: 0.091715976 | OQ8: =OO8-$OC8 -> 3 | OR8: 14 plus days | OS8: 36 | OT8: 0.10588235 | OU8: =OS8-$OC8 -> 8 | OV8: 14 plus days | OW8: 35 | OX8: 0.10479042 | OY8: =OW8-$OC8 -> 7 | OZ8: 14 plus days | PA8: 31 | PB8: 0.092814371 | PC8: =PA8-$OC8 -> 3 | PD8: 14 plus days | PE8: 28 | PF8: 0.08259587 | PG8: =PE8-$OC8 -> 0 | PH8: 14 plus days | PI8: 29 | PJ8: 0.085798817 | PK8: =PI8-$OC8 -> 1 | PL8: 14 plus days | PM8: 21 | PN8: 0.062686567 | PO8: =PM8-$OC8 -> -7 | PP8: 14 plus days | PQ8: 22 | PR8: 0.065281899 | PS8: =PQ8-$OC8 -> -6 | PT8: 14 plus days | PU8: 26 | PV8: 0.079268293 | PW8: =PU8-$OC8 -> -2 | PX8: 14 plus days | PY8: 24 | PZ8: 0.072289157 | QA8: =PY8-$OC8 -> -4 | QB8: 14 plus days | QC8: 23 | QD8: 0.073015873 | QE8: =QC8-$OC8 -> -5 | QF8: 14 plus days | QG8: 23 | QH8: 0.075163399 | QI8: =QG8-$OC8 -> -5 | QJ8: 14 plus days | QK8: 25 | QL8: 0.085910653 | QM8: =QK8-$OC8 -> -3 | QN8: 14 plus days | QO8: 30 | QP8: 0.10791367 | QQ8: =QO8-$OC8 -> 2 | QR8: 14 plus days | QS8: 29 | QT8: 0.11153846 | QU8: =QS8-$OC8 -> 1 | QV8: 14 plus days | QW8: 27 | QX8: 0.079881657 | QY8: =QW8-$OC8 -> -1 | QZ8: 14 plus days | RA8: 34 | RB8: 0.10149254 | RC8: =RA8-$OC8 -> 6 | RD8: 14 plus days | RE8: 34 | RF8: 0.099706745 | RG8: =RE8-$OC8 -> 6 | RH8: 14 plus days | RI8: 36 | RJ8: 0.10876133 | RK8: =RI8-$RE8 -> 2 | RL8: 14 plus days | RM8: 33 | RN8: 0.099697885 | RO8: =RM8-$RE8 -> -1 | RP8: 14 plus days | RQ8: 28 | RR8: 0.084084084 | RS8: =RQ8-$RE8 -> -6 | RT8: 14 plus days | RU8: 28 | RV8: 0.084337349 | RW8: =RU8-$RE8 -> -6 | RX8: 14 plus days | SA8: =RY8-$RE8 -> -34
A9: Less than 14 days | B9: 132 | C9: 0.33082707 | D9: Less than 14 days | E9: 104 | F9: 0.2464455 | G9: =E9-$B9 -> -28 | H9: Less than 14 days | I9: 104 | J9: 0.2464455 | K9: =I9-$B9 -> -28 | L9: Less than 14 days | M9: 95 | N9: 0.24234694 | O9: =M9-$B9 -> -37 | P9: Less than 14 days | Q9: 139 | R9: 0.42901235 | S9: =Q9-$B9 -> 7 | T9: Less than 14 days | U9: 87 | V9: 0.24857143 | W9: =U9-$B9 -> -45 | X9: Less than 14 days | Y9: 84 | Z9: 0.24137931 | AA9: =Y9-$B9 -> -48 | AB9: Less than 14 days | AC9: 100 | AD9: 0.28571429 | AE9: =AC9-$B9 -> -32 | AF9: Less than 14 days | AG9: 101 | AH9: 0.28857143 | AI9: =AG9-$B9 -> -31 | AJ9: Less than 14 days | AK9: 101 | AL9: 0.28857143 | AM9: =AK9-$B9 -> -31 | AO9: 86 | AP9: 0.25219941 | AQ9: =AO9-$B9 -> -46 | AR9: Less than 14 days | AS9: 88 | AT9: 0.25433526 | AU9: =AS9-$B9 -> -44 | AW9: 74 | AX9: 0.22769231 | AY9: =AW9-$B9 -> -58 | BA9: 77 | BB9: 0.23839009 | BC9: =BA9-$B9 -> -55 | BD9: Less than 14 days | BE9: 104 | BF9: 0.32298137 | BG9: =BE9-$B9 -> -28 | BH9: Less than 14 days | BI9: 93 | BJ9: 0.30194805 | BK9: =BI9-$B9 -> -39 | BL9: Less than 14 days | BM9: 100 | BN9: 0.3125 | BO9: =BM9-$B9 -> -32 | BP9: Less than 14 days | BQ9: 105 | BR9: 0.34539474 | BS9: =BQ9-$B9 -> -27 | BT9: Less than 14 days | BU9: 85 | BV9: 0.28145695 | BW9: =BU9-$B9 -> -47 | BX9: Less than 14 days | BY9: 95 | BZ9: 0.32646048 | CA9: =BY9-$B9 -> -37 | CB9: Less than 14 days | CC9: 78 | CD9: 0.30232558 | CE9: =CC9-$B9 -> -54 | CF9: Less than 14 days | CG9: 84 | CH9: 0.31343284 | CI9: =CG9-$B9 -> -48 | CJ9: Less than 14 days | CK9: 78 | CL9: 0.28467153 | CM9: =CK9-$B9 -> -54 | CN9: Less than 14 days | CO9: 76 | CP9: 0.26573427 | CQ9: =CO9-$B9 -> -56 | CR9: Less than 14 days | CS9: 79 | CT9: 0.27147766 | CU9: =CS9-$B9 -> -53 | CV9: Less than 14 days | CW9: 89 | CX9: 0.27899687 | CY9: =CW9-$B9 -> -43 | CZ9: Less than 14 days | DA9: 89 | DB9: 0.27899687 | DC9: =DA9-$BQ9 -> -16 | DD9: Less than 14 days | DE9: 82 | DF9: 0.26282051 | DG9: =DE9-$BQ9 -> -23 | DH9: Less than 14 days | DI9: 79 | DJ9: 0.25483871 | DK9: =DI9-$BQ9 -> -26 | DL9: Less than 14 days | DM9: 75 | DN9: 0.24671053 | DO9: =DM9-$BQ9 -> -30 | DP9: Less than 14 days | DQ9: 72 | DR9: 0.23151125 | DS9: =DQ9-$BQ9 -> -33 | DT9: Less than 14 days | DU9: 75 | DV9: 0.23809524 | DW9: =DU9-$BQ9 -> -30 | DX9: Less than 14 days | DY9: 66 | DZ9: 0.21428571 | EA9: =DY9-$BQ9 -> -39 | EB9: Less than 14 days | EC9: 69 | ED9: 0.22402597 | EE9: =EC9-$BQ9 -> -36 | EF9: Less than 14 days | EG9: 87 | EH9: 0.28064516 | EI9: =EG9-$BQ9 -> -18 | EJ9: Less than 14 days | EK9: 91 | EL9: 0.28616352 | EM9: =EK9-$BQ9 -> -14 | EN9: Less than 14 days | EO9: 94 | EP9: 0.29467085 | EQ9: =EO9-$BQ9 -> -11 | ER9: Less than 14 days | ES9: 81 | ET9: 0.26213592 | EU9: =ES9-$EO9 -> -13 | EV9: Less than 14 days | EW9: 81 | EX9: 0.27 | EY9: =EW9-$EO9 -> -13 | EZ9: Less than 14 days | FA9: 82 | FB9: 0.27062706 | FC9: =FA9-$EO9 -> -12 | FD9: Less than 14 days | FE9: 82 | FF9: 0.26537217 | FG9: =FE9-$EO9 -> -12 | FH9: Less than 14 days | FI9: 76 | FJ9: 0.24675325 | FK9: =FI9-$EO9 -> -18 | FL9: Less than 14 days | FM9: 77 | FN9: 0.25496689 | FO9: =FM9-$EO9 -> -17 | FP9: Less than 14 days | FQ9: 78 | FR9: 0.25742574 | FS9: =FQ9-$EO9 -> -16 | FT9: Less than 14 days | FU9: 76 | FV9: 0.24836601 | FW9: =FU9-$EO9 -> -18 | FX9: Less than 14 days | FY9: 73 | FZ9: 0.24013158 | GA9: =FY9-$EO9 -> -21 | GB9: Less than 14 days | GC9: 93 | GD9: 0.29245283 | GE9: =GC9-$EO9 -> -1 | GF9: Less than 14 days | GG9: 88 | GH9: 0.27672956 | GI9: =GG9-$EO9 -> -6 | GJ9: Less than 14 days | GK9: 92 | GL9: 0.2875 | GM9: =GK9-$EO9 -> -2 | GN9: Less than 14 days | GO9: 92 | GP9: 0.28482972 | GQ9: =GO9-$EO9 -> -2 | GR9: Less than 14 days | GS9: 89 | GT9: 0.28164557 | GU9: =GS9-$EO9 -> -5 | GV9: Less than 14 days | GW9: 82 | GX9: 0.26710098 | GY9: =GW9-$EO9 -> -12 | GZ9: Less than 14 days | HA9: 83 | HB9: 0.27124183 | HC9: =HA9-$EO9 -> -11 | HD9: Less than 14 days | HE9: 86 | HF9: 0.28382838 | HG9: =HE9-$EO9 -> -8 | HH9: Less than 14 days | HI9: 74 | HJ9: 0.24183007 | HK9: =HI9-$HE9 -> -12 | HL9: Less than 14 days | HM9: 86 | HN9: 0.26219512 | HO9: =HM9-$HE9 -> 0 | HP9: Less than 14 days | HQ9: 89 | HR9: 0.26726727 | HS9: =HQ9-$HE9 -> 3 | HT9: Less than 14 days | HU9: 95 | HV9: 0.27696793 | HW9: =HU9-$HE9 -> 9 | HX9: Less than 14 days | HY9: 95 | HZ9: 0.27616279 | IA9: =HY9-$HE9 -> 9 | IB9: Less than 14 days | IC9: 92 | ID9: 0.27299703 | IE9: =IC9-$HE9 -> 6 | IF9: Less than 14 days | IG9: 89 | IH9: 0.26969697 | II9: =IG9-$HE9 -> 3 | IJ9: Less than 14 days | IK9: 97 | IL9: 0.28613569 | IM9: =IK9-$HE9 -> 11 | IN9: Less than 14 days | IO9: 104 | IP9: 0.30409357 | IQ9: =IO9-$HE9 -> 18 | IR9: Less than 14 days | IS9: 110 | IT9: 0.31518625 | IU9: =IS9-$HE9 -> 24 | IV9: Less than 14 days | IW9: 91 | IX9: 0.27245509 | IY9: =IW9-$HE9 -> 5 | IZ9: Less than 14 days | JA9: 98 | JB9: 0.28405797 | JC9: =JA9-$HE9 -> 12 | JD9: Less than 14 days | JE9: 92 | JF9: 0.27058824 | JG9: =JE9-$HE9 -> 6 | JH9: Less than 14 days | JI9: 84 | JJ9: 0.246 | JK9: =JI9-$HE9 -> -2 | JL9: Less than 14 days | JM9: 91 | JN9: 0.26843658 | JO9: =JM9-$HE9 -> 5 | JP9: Less than 14 days | JQ9: 89 | JR9: 0.26567164 | JS9: =JQ9-$HE9 -> 3 | JT9: Less than 14 days | JU9: 93 | JV9: 0.28012048 | JW9: =JU9-$HE9 -> 7 | JX9: Less than 14 days | JY9: 93 | JZ9: 0.28012048 | KA9: =JY9-$HE9 -> 7 | KB9: Less than 14 days | KC9: 93 | KD9: 0.28012048 | KE9: =KC9-$HE9 -> 7 | KF9: Less than 14 days | KG9: 69 | KH9: 0.21296296 | KI9: =KG9-$HE9 -> -17 | KJ9: Less than 14 days | KK9: 65 | KL9: 0.1993865 | KM9: =KK9-$HE9 -> -21 | KN9: Less than 14 days | KO9: 68 | KP9: 0.20606061 | KQ9: =KO9-$HE9 -> -18 | KR9: Less than 14 days | KS9: 65 | KT9: 0.19817073 | KU9: =KS9-$HE9 -> -21 | KV9: Less than 14 days | KW9: 65 | KX9: 0.19817073 | KY9: =KW9-$HE9 -> -21 | KZ9: Less than 14 days | LA9: 60 | LB9: 0.18072289 | LC9: =LA9-$HE9 -> -26 | LD9: Less than 14 days | LE9: 53 | LF9: 0.16158537 | LG9: =LE9-$LA9 -> -7 | LH9: Less than 14 days | LI9: 59 | LJ9: 0.17824773 | LK9: =LI9-$LA9 -> -1 | LL9: Less than 14 days | LM9: 69 | LN9: 0.20414201 | LO9: =LM9-$LA9 -> 9 | LP9: Less than 14 days | LQ9: 77 | LR9: 0.22713864 | LS9: =LQ9-$LA9 -> 17 | LT9: Less than 14 days | LU9: 83 | LV9: 0.24127907 | LW9: =LU9-$LA9 -> 23 | LX9: Less than 14 days | LY9: 85 | LZ9: 0.24853801 | MA9: =LY9-$LA9 -> 25 | MB9: Less than 14 days | MC9: 92 | MD9: 0.27138643 | ME9: =MC9-$LA9 -> 32 | MF9: Less than 14 days | MG9: 101 | MH9: 0.29618768 | MI9: =MG9-$LA9 -> 41 | MJ9: Less than 14 days | MK9: 101 | ML9: 0.30059524 | MM9: =MK9-$LA9 -> 41 | MN9: Less than 14 days | MO9: 96 | MP9: 0.28402367 | MQ9: =MO9-$LA9 -> 36 | MR9: Less than 14 days | MS9: 80 | MT9: 0.23809524 | MU9: =MS9-$LA9 -> 20 | MV9: Less than 14 days | MW9: 88 | MX9: 0.25958702 | MY9: =MW9-$LA9 -> 28 | MZ9: Less than 14 days | NA9: 88 | NB9: 0.25882353 | NC9: =NA9-$LA9 -> 28 | ND9: Less than 14 days | NE9: 85 | NF9: 0.25147929 | NG9: =NE9-$LA9 -> 25 | NH9: Less than 14 days | NI9: 85 | NJ9: 0.25757576 | NK9: =NI9-$LA9 -> 25 | NL9: Less than 14 days | NM9: 64 | NN9: 0.19692308 | NO9: =NM9-$LA9 -> 4 | NP9: Less than 14 days | NQ9: 73 | NR9: 0.21921922 | NS9: =NQ9-$LA9 -> 13 | NT9: Less than 14 days | NU9: 89 | NV9: 0.25872093 | NW9: =NU9-$LA9 -> 29 | NX9: Less than 14 days | NY9: 90 | NZ9: 0.25936599 | OA9: =NY9-$LA9 -> 30 | OB9: Less than 14 days | OC9: 84 | OD9: 0.25 | OE9: =OC9-$LA9 -> 24 | OF9: Less than 14 days | OG9: 82 | OH9: 0.24550898 | OI9: =OG9-$OC9 -> -2 | OJ9: Less than 14 days | OK9: 91 | OL9: 0.26686217 | OM9: =OK9-$OC9 -> 7 | ON9: Less than 14 days | OO9: 87 | OP9: 0.25739645 | OQ9: =OO9-$OC9 -> 3 | OR9: Less than 14 days | OS9: 81 | OT9: 0.23823529 | OU9: =OS9-$OC9 -> -3 | OV9: Less than 14 days | OW9: 75 | OX9: 0.2245509 | OY9: =OW9-$OC9 -> -9 | OZ9: Less than 14 days | PA9: 76 | PB9: 0.22754491 | PC9: =PA9-$OC9 -> -8 | PD9: Less than 14 days | PE9: 85 | PF9: 0.25073746 | PG9: =PE9-$OC9 -> 1 | PH9: Less than 14 days | PI9: 82 | PJ9: 0.24260355 | PK9: =PI9-$OC9 -> -2 | PL9: Less than 14 days | PM9: 83 | PN9: 0.24776119 | PO9: =PM9-$OC9 -> -1 | PP9: Less than 14 days | PQ9: 85 | PR9: 0.25222552 | PS9: =PQ9-$OC9 -> 1 | PT9: Less than 14 days | PU9: 75 | PV9: 0.22865854 | PW9: =PU9-$OC9 -> -9 | PX9: Less than 14 days | PY9: 78 | PZ9: 0.23493976 | QA9: =PY9-$OC9 -> -6 | QB9: Less than 14 days | QC9: 73 | QD9: 0.23174603 | QE9: =QC9-$OC9 -> -11 | QF9: Less than 14 days | QG9: 67 | QH9: 0.21895425 | QI9: =QG9-$OC9 -> -17 | QJ9: Less than 14 days | QK9: 56 | QL9: 0.19243986 | QM9: =QK9-$OC9 -> -28 | QN9: Less than 14 days | QO9: 41 | QP9: 0.14748201 | QQ9: =QO9-$OC9 -> -43 | QR9: Less than 14 days | QS9: 38 | QT9: 0.14615385 | QU9: =QS9-$OC9 -> -46 | QV9: Less than 14 days | QW9: 92 | QX9: 0.27218935 | QY9: =QW9-$OC9 -> 8 | QZ9: Less than 14 days | RA9: 81 | RB9: 0.24179104 | RC9: =RA9-$OC9 -> -3 | RD9: Less than 14 days | RE9: 92 | RF9: 0.26979472 | RG9: =RE9-$OC9 -> 8 | RH9: Less than 14 days | RI9: 78 | RJ9: 0.23564955 | RK9: =RI9-$RE9 -> -14 | RL9: Less than 14 days | RM9: 85 | RN9: 0.25679758 | RO9: =RM9-$RE9 -> -7 | RP9: Less than 14 days | RQ9: 91 | RR9: 0.27327327 | RS9: =RQ9-$RE9 -> -1 | RT9: Less than 14 days | RU9: 90 | RV9: 0.27108434 | RW9: =RU9-$RE9 -> -2 | RX9: Less than 14 days | SA9: =RY9-$RE9 -> -92
A10: Grand Total | B10: 399 | C10: 1 | D10: Grand Total | E10: 422 | F10: 1 | G10: =E10-$B10 -> 23 | H10: Grand Total | I10: 422 | J10: 1 | K10: =I10-$B10 -> 23 | L10: Grand Total | M10: 392 | N10: 1 | O10: =M10-$B10 -> -7 | P10: Grand Total | Q10: 324 | R10: 1 | S10: =Q10-$B10 -> -75 | T10: Grand Total | U10: 350 | V10: 1 | W10: =U10-$B10 -> -49 | X10: Grand Total | Y10: 348 | Z10: 1 | AA10: =Y10-$B10 -> -51 | AB10: Grand Total | AC10: 350 | AD10: 1 | AE10: =AC10-$B10 -> -49 | AF10: Grand Total | AG10: 350 | AH10: 1 | AI10: =AG10-$B10 -> -49 | AJ10: Grand Total | AK10: 350 | AL10: 1 | AM10: =AK10-$B10 -> -49 | AO10: 341 | AP10: 1 | AQ10: =AO10-$B10 -> -58 | AR10: Grand Total | AS10: 346 | AT10: 1 | AU10: =AS10-$B10 -> -53 | AW10: 325 | AX10: 1 | AY10: =AW10-$B10 -> -74 | BA10: 323 | BB10: 1 | BC10: =BA10-$B10 -> -76 | BD10: Grand Total | BE10: 322 | BF10: 1 | BG10: =BE10-$B10 -> -77 | BH10: Grand Total | BI10: 308 | BJ10: 1 | BK10: =BI10-$B10 -> -91 | BL10: Grand Total | BM10: 320 | BN10: 1 | BO10: =BM10-$B10 -> -79 | BP10: Grand Total | BQ10: 304 | BR10: 1 | BS10: =BQ10-$B10 -> -95 | BT10: Grand Total | BU10: 302 | BV10: 1 | BW10: =BU10-$B10 -> -97 | BX10: Grand Total | BY10: 291 | BZ10: 1 | CA10: =BY10-$B10 -> -108 | CB10: Grand Total | CC10: 258 | CD10: 1 | CE10: =CC10-$B10 -> -141 | CF10: Grand Total | CG10: 268 | CH10: 1 | CI10: =CG10-$B10 -> -131 | CJ10: Grand Total | CK10: 274 | CL10: 1 | CM10: =CK10-$B10 -> -125 | CN10: Grand Total | CO10: 286 | CP10: 1 | CQ10: =CO10-$B10 -> -113 | CR10: Grand Total | CS10: 291 | CT10: 1 | CU10: =CS10-$B10 -> -108 | CV10: Grand Total | CW10: 319 | CX10: 1 | CY10: =CW10-$B10 -> -80 | CZ10: Grand Total | DA10: 319 | DB10: 1 | DC10: =DA10-$BQ10 -> 15 | DD10: Grand Total | DE10: 312 | DF10: 1 | DG10: =DE10-$BQ10 -> 8 | DH10: Grand Total | DI10: 310 | DJ10: 1 | DK10: =DI10-$BQ10 -> 6 | DL10: Grand Total | DM10: 304 | DN10: 1 | DO10: =DM10-$BQ10 -> 0 | DP10: Grand Total | DQ10: 311 | DR10: 1 | DS10: =DQ10-$BQ10 -> 7 | DT10: Grand Total | DU10: 315 | DV10: 1 | DW10: =DU10-$BQ10 -> 11 | DX10: Grand Total | DY10: 308 | DZ10: 1 | EA10: =DY10-$BQ10 -> 4 | EB10: Grand Total | EC10: 308 | ED10: 1 | EE10: =EC10-$BQ10 -> 4 | EF10: Grand Total | EG10: 310 | EH10: 1 | EI10: =EG10-$BQ10 -> 6 | EJ10: Grand Total | EK10: 318 | EL10: 1 | EM10: =EK10-$BQ10 -> 14 | EN10: Grand Total | EO10: 319 | EP10: 1 | EQ10: =EO10-$BQ10 -> 15 | ER10: Grand Total | ES10: 309 | ET10: 1 | EU10: =ES10-$EO10 -> -10 | EV10: Grand Total | EW10: 300 | EX10: 1 | EY10: =EW10-$EO10 -> -19 | EZ10: Grand Total | FA10: 303 | FB10: 1 | FC10: =FA10-$EO10 -> -16 | FD10: Grand Total | FE10: 309 | FF10: 1 | FG10: =FE10-$EO10 -> -10 | FH10: Grand Total | FI10: 308 | FJ10: 1 | FK10: =FI10-$EO10 -> -11 | FL10: Grand Total | FM10: 302 | FN10: 1 | FO10: =FM10-$EO10 -> -17 | FP10: Grand Total | FQ10: 303 | FR10: 1 | FS10: =FQ10-$EO10 -> -16 | FT10: Grand Total | FU10: 306 | FV10: 1 | FW10: =FU10-$EO10 -> -13 | FX10: Grand Total | FY10: 304 | FZ10: 1 | GA10: =FY10-$EO10 -> -15 | GB10: Grand Total | GC10: 318 | GD10: 1 | GE10: =GC10-$EO10 -> -1 | GF10: Grand Total | GG10: 318 | GH10: 1 | GI10: =GG10-$EO10 -> -1 | GJ10: Grand Total | GK10: 320 | GL10: 1 | GM10: =GK10-$EO10 -> 1 | GN10: Grand Total | GO10: 323 | GP10: 1 | GQ10: =GO10-$EO10 -> 4 | GR10: Grand Total | GS10: 316 | GT10: 1 | GU10: =GS10-$EO10 -> -3 | GV10: Grand Total | GW10: 307 | GX10: 1 | GY10: =GW10-$EO10 -> -12 | GZ10: Grand Total | HA10: 306 | HB10: 1 | HC10: =HA10-$EO10 -> -13 | HD10: Grand Total | HE10: 303 | HF10: 1 | HG10: =HE10-$EO10 -> -16 | HH10: Grand Total | HI10: 306 | HJ10: 1 | HK10: =HI10-$HE10 -> 3 | HL10: Grand Total | HM10: 328 | HN10: 1 | HO10: =HM10-$HE10 -> 25 | HP10: Grand Total | HQ10: 333 | HR10: 1 | HS10: =HQ10-$HE10 -> 30 | HT10: Grand Total | HU10: 343 | HV10: 1 | HW10: =HU10-$HE10 -> 40 | HX10: Grand Total | HY10: 344 | HZ10: 1 | IA10: =HY10-$HE10 -> 41 | IB10: Grand Total | IC10: 337 | ID10: 1 | IE10: =IC10-$HE10 -> 34 | IF10: Grand Total | IG10: 330 | IH10: 1 | II10: =IG10-$HE10 -> 27 | IJ10: Grand Total | IK10: 339 | IL10: 1 | IM10: =IK10-$HE10 -> 36 | IN10: Grand Total | IO10: 342 | IP10: 1 | IQ10: =IO10-$HE10 -> 39 | IR10: Grand Total | IS10: 349 | IT10: 1 | IU10: =IS10-$HE10 -> 46 | IV10: Grand Total | IW10: 334 | IX10: 1 | IY10: =IW10-$HE10 -> 31 | IZ10: Grand Total | JA10: 345 | JB10: 1 | JC10: =JA10-$HE10 -> 42 | JD10: Grand Total | JE10: 340 | JF10: 1 | JG10: =JE10-$HE10 -> 37 | JH10: Grand Total | JI10: 341 | JJ10: 1 | JK10: =JI10-$HE10 -> 38 | JL10: Grand Total | JM10: 339 | JN10: 1 | JO10: =JM10-$HE10 -> 36 | JP10: Grand Total | JQ10: 335 | JR10: 1 | JS10: =JQ10-$HE10 -> 32 | JT10: Grand Total | JU10: 332 | JV10: 1 | JW10: =JU10-$HE10 -> 29 | JX10: Grand Total | JY10: 332 | JZ10: 1 | KA10: =JY10-$HE10 -> 29 | KB10: Grand Total | KC10: 332 | KD10: 1 | KE10: =KC10-$HE10 -> 29 | KF10: Grand Total | KG10: 324 | KH10: 1 | KI10: =KG10-$HE10 -> 21 | KJ10: Grand Total | KK10: 326 | KL10: 1 | KM10: =KK10-$HE10 -> 23 | KN10: Grand Total | KO10: 330 | KP10: 1 | KQ10: =KO10-$HE10 -> 27 | KR10: Grand Total | KS10: 328 | KT10: 1 | KU10: =KS10-$HE10 -> 25 | KV10: Grand Total | KW10: 328 | KX10: 1 | KY10: =KW10-$HE10 -> 25 | KZ10: Grand Total | LA10: 332 | LB10: 1 | LC10: =LA10-$HE10 -> 29 | LD10: Grand Total | LE10: 328 | LF10: 1 | LG10: =LE10-$LA10 -> -4 | LH10: Grand Total | LI10: 331 | LJ10: 1 | LK10: =LI10-$LA10 -> -1 | LL10: Grand Total | LM10: 338 | LN10: 1 | LO10: =LM10-$LA10 -> 6 | LP10: Grand Total | LQ10: 339 | LR10: 1 | LS10: =LQ10-$LA10 -> 7 | LT10: Grand Total | LU10: 344 | LV10: 1 | LW10: =LU10-$LA10 -> 12 | LX10: Grand Total | LY10: 342 | LZ10: 1 | MA10: =LY10-$LA10 -> 10 | MB10: Grand Total | MC10: 339 | MD10: 1 | ME10: =MC10-$LA10 -> 7 | MF10: Grand Total | MG10: 341 | MH10: 1 | MI10: =MG10-$LA10 -> 9 | MJ10: Grand Total | MK10: 336 | ML10: 1 | MM10: =MK10-$LA10 -> 4 | MN10: Grand Total | MO10: 338 | MP10: 1 | MQ10: =MO10-$LA10 -> 6 | MR10: Grand Total | MS10: 336 | MT10: 1 | MU10: =MS10-$LA10 -> 4 | MV10: Grand Total | MW10: 339 | MX10: 1 | MY10: =MW10-$LA10 -> 7 | MZ10: Grand Total | NA10: 340 | NB10: 1 | NC10: =NA10-$LA10 -> 8 | ND10: Grand Total | NE10: 338 | NF10: 1 | NG10: =NE10-$LA10 -> 6 | NH10: Grand Total | NI10: 330 | NJ10: 1 | NK10: =NI10-$LA10 -> -2 | NL10: Grand Total | NM10: 325 | NN10: 1 | NO10: =NM10-$LA10 -> -7 | NP10: Grand Total | NQ10: 333 | NR10: 1 | NS10: =NQ10-$LA10 -> 1 | NT10: Grand Total | NU10: 344 | NV10: 1 | NW10: =NU10-$LA10 -> 12 | NX10: Grand Total | NY10: 347 | NZ10: 1 | OA10: =NY10-$LA10 -> 15 | OB10: Grand Total | OC10: 336 | OD10: 1 | OE10: =OC10-$LA10 -> 4 | OF10: Grand Total | OG10: 334 | OH10: 1 | OI10: =OG10-$OC10 -> -2 | OJ10: Grand Total | OK10: 341 | OL10: 1 | OM10: =OK10-$OC10 -> 5 | ON10: Grand Total | OO10: 338 | OP10: 1 | OQ10: =OO10-$OC10 -> 2 | OR10: Grand Total | OS10: 340 | OT10: 1 | OU10: =OS10-$OC10 -> 4 | OV10: Grand Total | OW10: 334 | OX10: 1 | OY10: =OW10-$OC10 -> -2 | OZ10: Grand Total | PA10: 334 | PB10: 1 | PC10: =PA10-$OC10 -> -2 | PD10: Grand Total | PE10: 339 | PF10: 1 | PG10: =PE10-$OC10 -> 3 | PH10: Grand Total | PI10: 338 | PJ10: 1 | PK10: =PI10-$OC10 -> 2 | PL10: Grand Total | PM10: 335 | PN10: 1 | PO10: =PM10-$OC10 -> -1 | PP10: Grand Total | PQ10: 337 | PR10: 1 | PS10: =PQ10-$OC10 -> 1 | PT10: Grand Total | PU10: 328 | PV10: 1 | PW10: =PU10-$OC10 -> -8 | PX10: Grand Total | PY10: 332 | PZ10: 1 | QA10: =PY10-$OC10 -> -4 | QB10: Grand Total | QC10: 315 | QD10: 1 | QE10: =QC10-$OC10 -> -21 | QF10: Grand Total | QG10: 306 | QH10: 1 | QI10: =QG10-$OC10 -> -30 | QJ10: Grand Total | QK10: 291 | QL10: 1 | QM10: =QK10-$OC10 -> -45 | QN10: Grand Total | QO10: 278 | QP10: 1 | QQ10: =QO10-$OC10 -> -58 | QR10: Grand Total | QS10: 260 | QT10: 1 | QU10: =QS10-$OC10 -> -76 | QV10: Grand Total | QW10: 338 | QX10: 1 | QY10: =QW10-$OC10 -> 2 | QZ10: Grand Total | RA10: 335 | RB10: 1 | RC10: =RA10-$OC10 -> -1 | RD10: Grand Total | RE10: 341 | RF10: 1 | RG10: =RE10-$OC10 -> 5 | RH10: Grand Total | RI10: 331 | RJ10: 1 | RK10: =RI10-$RE10 -> -10 | RL10: Grand Total | RM10: 331 | RN10: 1 | RO10: =RM10-$RE10 -> -10 | RP10: Grand Total | RQ10: 333 | RR10: 1 | RS10: =RQ10-$RE10 -> -8 | RT10: Grand Total | RU10: 332 | RV10: 1 | RW10: =RU10-$RE10 -> -9 | RX10: Grand Total | SA10: =RY10-$RE10 -> -341
