Workbook
Name Ops: 'Ops Team'!$A$1:$C$30
Name Slicer_Date_of_this_request: #N/A
Name Slicer_New_Rental_or_Extension: #N/A
Name Slicer_Rental_Approved: #N/A
Name Slicer_Truck_Breakdown_or_New_Hire: #N/A
Name Slicer_Unit_Number: #N/A
Name TPMSLU: #REF!

Sheet Addresses
A1: TRIM ENT ID | B1: Emplid | C1: Name | D1: Enterprise ID | E1: Status as of 2025-09-30 | F1: Job Code | G1: Job Title | H1: Tech Type | I1: Company | J1: Region | K1: District | L1: Location | M1: Loc City | N1: Loc State | O1: Orig Hire Dt | P1: Last Hire Dt | Q1: Service Dt | R1: Days of Svc | S1: Yrs of Svc | T1: Svc Category | U1: Empl Address1 | V1: Empl Address2 | W1: Empl City | X1: Empl State | Y1: Empl Postal
A2: =TRIM(D2) | B2: 11024630301 | C2: SPRADLING,RYAN T | E2: T | F2: HS2003 | G2: Service Technician 1, In-Home | H2: In Home Tech | I2: TSH | J2: 58890 | K2: 08184 | L2: 28081 | M2: Sacramento | N2: CA | O2: 45662 | P2: 45662 | Q2: 45662 | R2: 267 | S2: 0 | T2: 6 Mo - 1 Year | U2: 720 SHELL AVE APT 101 | W2: MARTINEZ | X2: CA | Y2: 94553
A3: =TRIM(D3) | B3: 11024631201 | C3: LACEY,ANTHONY | E3: A | F3: HS2023 | G3: Service Technician 2, In-Home | H3: In Home Tech | I3: TSH | J3: 58890 | K3: 08184 | L3: 28045 | M3: Sacramento | N3: CA | O3: 45928 | P3: 45928 | Q3: 45928 | R3: 1 | S3: 0 | T3: 0-30 Days | U3: 769 CAPRICE WAY | W3: CHICO | X3: CA | Y3: 95973
A4: =TRIM(D4) | B4: 31024630673 | C4: RAMOS,DION | E4: T | F4: HS2003 | G4: Service Technician 1, In-Home | H4: In Home Tech | I4: TSH | J4: 58850 | K4: 07435 | L4: 28094 | M4: Winter Park | N4: FL | O4: 45795 | P4: 45795 | Q4: 45795 | R4: 134 | S4: 0 | T4: 91 Days - 6 Months | U4: 1304 SW 22ND PL | W4: CAPE CORAL | X4: FL | Y4: 33991
A5: =TRIM(D5) | B5: 81024630418 | C5: MORRIS,SHAWN | E5: T | F5: UHS018 | G5: Service Technician HV, In-Home | H5: In Home Tech | I5: TSH | J5: 58850 | K5: 08309 | L5: 24042 | M5: Sterling Heights | N5: MI | O5: 45697 | P5: 45697 | Q5: 45697 | R5: 232 | S5: 0 | T5: 6 Mo - 1 Year | U5: 2525 IVY PL. | W5: TOLEDO | X5: OH | Y5: 43613
A6: =TRIM(D6) -> aacuna | B6: 91022642419 | C6: ACUNA JR,ARTURO | D6: aacuna | E6: A | F6: HS2018 | G6: Service Tech - Modified Duty | H6: In Home Tech | I6: TSH | J6: 58890 | K6: 07108 | L6: 28042 | M6: Fontana | N6: CA | O6: 38783 | P6: 45123 | Q6: 45123 | R6: 806 | S6: 2 | T6: 1-3 Years | U6: 867 N 2nd St | V6: Unit 2293 | W6: El Cajon | X6: CA | Y6: 92021
A7: =TRIM(D7) -> aadamow | B7: 91024630879 | C7: ADAMOWSKI,AUSTIN T | D7: aadamow | E7: A | F7: HS9661 | G7: Service Technician 3, In-Home | H7: In Home Tech | I7: TSH | J7: 58890 | K7: 08555 | L7: 08220 | M7: New Berlin | N7: WI | O7: 45858 | P7: 45858 | Q7: 45858 | R7: 71 | S7: 0 | T7: 61-90 Days | U7: 525 KELVINGTON DRIVE #2 | W7: SUN PRAIRIE | X7: WI | Y7: 53590
A8: =TRIM(D8) -> aaguil0 | B8: 21024624182 | C8: AGUILAR,ANTHONY I | D8: aaguil0 | E8: A | F8: HS1782 | G8: HVAC Lead Installer | H8: HVAC Tech | I8: TSH | J8: 58890 | K8: 07108 | L8: 28042 | M8: Fontana | N8: CA | O8: 44770 | P8: 44770 | Q8: 44770 | R8: 1159 | S8: 3 | T8: 3-6 Years | U8: 4126 village dr | V8: Apt C | W8: Chino Hills | X8: CA | Y8: 91709
A9: =TRIM(D9) -> aalbarr | B9: 41024626464 | C9: ALBARRAN,ARTURO | D9: aalbarr | E9: T | F9: HS2305 | G9: HVAC Svc Tech II, Break/Fix | H9: HVAC Tech | I9: TSH | J9: 58890 | K9: 08555 | L9: 28037 | M9: Hoffman Estates | N9: IL | O9: 45032 | P9: 45032 | Q9: 45032 | R9: 897 | S9: 2 | T9: 1-3 Years | U9: 214 EVOLUTION | W9: HIGHWOOD | X9: IL | Y9: 60040
A10: =TRIM(D10) -> aalexa5 | B10: 11024064791 | C10: ALEXANDER,andy E | D10: aalexa5 | E10: A | F10: HS2003 | G10: Service Technician 1, In-Home | H10: In Home Tech | I10: TSH | J10: 58890 | K10: 07088 | L10: 28056 | M10: El Cajon | N10: CA | O10: 41736 | P10: 41736 | Q10: 41736 | R10: 4193 | S10: 11 | T10: 6-15 Years | U10: 4026 camino paz | W10: Spring Valley | X10: CA | Y10: 91977
A11: =TRIM(D11) -> aalnajj | B11: 81024627928 | C11: ALNAJJAR,ABDELRAHMAN | D11: aalnajj | E11: L | F11: HS2003 | G11: Service Technician 1, In-Home | H11: In Home Tech | I11: TSH | J11: 58850 | K11: 07435 | L11: 28240 | M11: Hialeah | N11: FL | O11: 45221 | P11: 45221 | Q11: 45221 | R11: 708 | S11: 1 | T11: 1-3 Years | U11: 6495 SHORELINE DRIVE | V11: APT8502 | W11: SAINT PETERSBURG | X11: FL | Y11: 33708
A12: =TRIM(D12) -> AALVARA | B12: 01021240600 | C12: ALVARADO,AUGUSTINE | D12: AALVARA | E12: A | F12: HS2003 | G12: Service Technician 1, In-Home | H12: In Home Tech | I12: TSH | J12: 58890 | K12: 07995 | L12: 28224 | M12: Farmers Branch | N12: TX | O12: 32656 | P12: 32656 | Q12: 32656 | R12: 13273 | S12: 36 | T12: 16+ Years | U12: 804 NORTH CR 1450 | W12: LUBBOCK | X12: TX | Y12: 79416
A13: =TRIM(D13) -> aanacle | B13: 81024627258 | C13: ANACLETO,ANTONIO N | D13: aanacle | E13: T | F13: HS2023 | G13: Service Technician 2, In-Home | H13: In Home Tech | I13: TSH | J13: 58850 | K13: 07435 | L13: 28240 | M13: Hialeah | N13: FL | O13: 45144 | P13: 45144 | Q13: 45144 | R13: 785 | S13: 2 | T13: 1-3 Years | U13: 4306 GINGER COVE DR | V13: APARTMENT F | W13: TAMPA | X13: FL | Y13: 33634
A14: =TRIM(D14) -> aander2 | B14: 41024630294 | C14: ANDERSON,ANGELO | D14: aander2 | E14: A | F14: HS2308 | G14: HVAC Svc Tech I, Break/Fix | H14: HVAC Tech | I14: TSH | J14: 58850 | K14: 08175 | L14: 28121 | M14: Richmond | N14: VA | O14: 45676 | P14: 45676 | Q14: 45676 | R14: 253 | S14: 0 | T14: 6 Mo - 1 Year | U14: 25 Kyle Dr | W14: Garner | X14: NC | Y14: 27529
A15: =TRIM(D15) -> aaprim | B15: 51024631145 | C15: APRIM,ADAM L | D15: aaprim | E15: A | F15: HS1782 | G15: HVAC Lead Installer | H15: HVAC Tech | I15: TSH | J15: 58890 | K15: 08555 | L15: 28037 | M15: Hoffman Estates | N15: IL | O15: 45914 | P15: 45914 | Q15: 45914 | R15: 15 | S15: 0 | T15: 0-30 Days | U15: 183 N EAST RIVER RD | V15: C1 | W15: DES PLAINES | X15: IL | Y15: 60016
A16: =TRIM(D16) -> AARELLA | B16: 91023308459 | C16: ARELLANO,ANTHONY R | D16: AARELLA | E16: A | F16: HS2014 | G16: Team Lead Technician | H16: In Home Tech | I16: TSH | J16: 58890 | K16: 08184 | L16: 28081 | M16: Sacramento | N16: CA | O16: 40018 | P16: 40018 | Q16: 40018 | R16: 5911 | S16: 16 | T16: 16+ Years | U16: 27492 ORLANDO AVE | W16: HAYWARD | X16: CA | Y16: 94545
A17: =TRIM(D17) -> aarnold | B17: 91024631259 | C17: ARNOLD,ANTHONY J | D17: aarnold | E17: A | O17: 45935 | Q17: 45935 | U17: 7326 KENSINGTON DR. W | W17: NORTHWEST FORT WAYNE | X17: IN | Y17: 46818
A18: =TRIM(D18) -> aasghar | B18: 71024627287 | C18: ASGHARI,AHMAD OMAID | D18: aasghar | E18: A | F18: HS9661 | G18: Service Technician 3, In-Home | H18: In Home Tech | I18: TSH | J18: 58850 | K18: 03132 | L18: 28003 | M18: Linthicum Hts | N18: MD | O18: 45165 | P18: 45165 | Q18: 45165 | R18: 764 | S18: 2 | T18: 1-3 Years | U18: 8900 golden oak dr | V18: Apt J | W18: MANASSAS | X18: VA | Y18: 20109
A19: =TRIM(D19) -> aash0 | B19: 21024627192 | C19: ASH,AUSTIN | D19: aash0 | E19: T | F19: HS9661 | G19: Service Technician 3, In-Home | H19: In Home Tech | I19: TSH | J19: 58890 | K19: 08169 | L19: 28059 | M19: Salt Lake Cty | N19: UT | O19: 45130 | P19: 45130 | Q19: 45130 | R19: 799 | S19: 2 | T19: 1-3 Years | U19: 433 S 1210 E | W19: PLEASANT GROVE | X19: UT | Y19: 84062
A20: =TRIM(D20) -> AATRISC | B20: 71021845617 | C20: ATRISCO,ANGEL | D20: AATRISC | E20: A | F20: HS2003 | G20: Service Technician 1, In-Home | H20: In Home Tech | I20: TSH | J20: 58890 | K20: 08366 | L20: 28049 | M20: Fresno | N20: CA | O20: 36836 | P20: 36836 | Q20: 36836 | R20: 9093 | S20: 24 | T20: 16+ Years | U20: 996 San Gabriel | W20: Soledad | X20: CA | Y20: 93960
A21: =TRIM(D21) -> aatta | B21: 01024614750 | C21: Atta,Abdul M | D21: aatta | E21: A | F21: HS2003 | G21: Service Technician 1, In-Home | H21: In Home Tech | I21: TSH | J21: 58850 | K21: 03132 | L21: 28003 | M21: Linthicum Hts | N21: MD | O21: 44111 | P21: 44111 | Q21: 44111 | R21: 1818 | S21: 4 | T21: 3-6 Years | U21: 1961 Gableridge Turn | V21: Apt 301 | W21: Woodbridge | X21: VA | Y21: 22191
A22: =TRIM(D22) -> aayubi | B22: 01024561620 | C22: Ayubi,Amir E | D22: aayubi | E22: L | F22: HS2305 | G22: HVAC Svc Tech II, Break/Fix | H22: HVAC Tech | I22: TSH | J22: 58890 | K22: 07088 | L22: 28205 | M22: Mesa | N22: AZ | O22: 43409 | P22: 43409 | Q22: 43409 | R22: 2520 | S22: 6 | T22: 6-15 Years | U22: 1116 N 11TH AVE | W22: TUCSON | X22: AZ | Y22: 85705
A23: =TRIM(D23) -> abalice | B23: 11024624121 | C23: BALICE,ANTHONY | D23: abalice | E23: A | F23: HS2305 | G23: HVAC Svc Tech II, Break/Fix | H23: HVAC Tech | I23: TSH | J23: 58890 | K23: 08555 | L23: 28037 | M23: Hoffman Estates | N23: IL | O23: 44785 | P23: 44785 | Q23: 44785 | R23: 1144 | S23: 3 | T23: 3-6 Years | U23: 13619 ASPLAND DRIVE | W23: ROCKTON | X23: IL | Y23: 61072
A24: =TRIM(D24) -> abautis | B24: 71024622537 | C24: BAUTISTA VILLANUEVA,ALEX | D24: abautis | E24: A | F24: HS2003 | G24: Service Technician 1, In-Home | H24: In Home Tech | I24: TSH | J24: 58890 | K24: 07108 | L24: 28042 | M24: Fontana | N24: CA | O24: 44609 | P24: 44609 | Q24: 44609 | R24: 1320 | S24: 3 | T24: 3-6 Years | U24: 12913 RAMSEY DR. | W24: LA MIRADA | X24: CA | Y24: 90638
A25: =TRIM(D25) -> ABECKLE | B25: 31023010323 | C25: BECKLES,ANTON C | D25: ABECKLE | E25: T | F25: HS2023 | G25: Service Technician 2, In-Home | H25: In Home Tech | I25: TSH | J25: 58850 | K25: 04766 | L25: 28125 | M25: Louisville | N25: KY | O25: 39433 | P25: 39433 | Q25: 39433 | R25: 6496 | S25: 17 | T25: 16+ Years | U25: 2011 maple view lane | W25: Indian trail | X25: NC | Y25: 28079
A26: =TRIM(D26) -> ABEHLE | B26: 61021971066 | C26: BEHLER,ADAM C | D26: ABEHLE | E26: A | F26: HS2306 | G26: HVAC Technician Supervisor | H26: HVAC Tech | I26: TSH | J26: 58890 | K26: 08184 | L26: 28045 | M26: Sacramento | N26: CA | O26: 37137 | P26: 37137 | Q26: 37137 | R26: 8792 | S26: 24 | T26: 16+ Years | U26: 2695 Hopi Ct | W26: Cameron Park | X26: CA | Y26: 95682
A27: =TRIM(D27) -> abejte | B27: 11023930111 | C27: Bejte,Arben | D27: abejte | E27: A | F27: HS2023 | G27: Service Technician 2, In-Home | H27: In Home Tech | I27: TSH | J27: 58850 | K27: 07670 | L27: 28009 | M27: Danvers | N27: MA | O27: 41396 | P27: 41396 | Q27: 41396 | R27: 4533 | S27: 12 | T27: 6-15 Years | U27: 440 north ave | V27: apt 90 | W27: haverhill | X27: MA | Y27: 01830
A28: =TRIM(D28) -> aberik | B28: 11024631171 | C28: BERIK,ASKHAT | D28: aberik | E28: A | F28: HS2023 | G28: Service Technician 2, In-Home | H28: In Home Tech | I28: TSH | J28: 58890 | K28: 08555 | L28: 28037 | M28: Hoffman Estates | N28: IL | O28: 45914 | P28: 45914 | Q28: 45914 | R28: 15 | S28: 0 | T28: 0-30 Days | U28: 2335 SEDGFIELD CT | W28: SCHAUMBURG | X28: IL | Y28: 60194
A29: =TRIM(D29) -> abiblej | B29: 71024198517 | C29: BIBLE JR,ARTHUR L | D29: abiblej | E29: A | F29: HS9661 | G29: Service Technician 3, In-Home | H29: In Home Tech | I29: TSH | J29: 58890 | K29: 08228 | L29: 28040 | M29: Portland | N29: OR | O29: 42038 | P29: 42038 | Q29: 42038 | R29: 3891 | S29: 10 | T29: 6-15 Years | U29: 1771 Myrtle Street | W29: Baker City | X29: OR | Y29: 97814
A30: =TRIM(D30) -> ablake0 | B30: 11024335191 | C30: BLAKE Sr.,AARON R | D30: ablake0 | E30: T | F30: HS2305 | G30: HVAC Svc Tech II, Break/Fix | H30: HVAC Tech | I30: TSH | J30: 58850 | K30: 03132 | L30: 28003 | M30: Linthicum Hts | N30: MD | O30: 42432 | P30: 42432 | Q30: 42432 | R30: 3497 | S30: 9 | T30: 6-15 Years | U30: 3907 BURNS COURT S.E | W30: WASHINGTON | X30: DC | Y30: 20019
A31: =TRIM(D31) -> abland | B31: 81004652898 | C31: BLAND,AMIR | D31: abland | E31: A | F31: HS1022 | G31: Service Tech 2 Trainee, IH | H31: In Home Tech | I31: TSH | J31: 58850 | K31: 08035 | L31: 28085 | M31: College Park | N31: GA | O31: 39032 | P31: 45851 | Q31: 45851 | R31: 78 | S31: 0 | T31: 61-90 Days | U31: 1075 Chapman Circle | W31: Stone Mountain | X31: GA | Y31: 30088
A32: =TRIM(D32) -> abrady | B32: 11024628021 | C32: Brady,Andrew Mitchel | D32: abrady | E32: T | F32: HS2063 | G32: Service Technician HV, In-Home | H32: In Home Tech | I32: TSH | J32: 58850 | K32: 08175 | L32: 28121 | M32: Richmond | N32: VA | O32: 45235 | P32: 45235 | Q32: 45235 | R32: 694 | S32: 1 | T32: 1-3 Years | U32: 924 Tiffany ln | W32: Conway | X32: SC | Y32: 29526
A33: =TRIM(D33) -> ABRANTL | B33: 81021017628 | C33: BRANTLEY,AARON | D33: ABRANTL | E33: A | F33: HS1992 | G33: Service Tech 1, IH | H33: In Home Tech | I33: TSH | J33: 58850 | K33: 08035 | L33: 28085 | M33: College Park | N33: GA | O33: 26742 | P33: 26742 | Q33: 26742 | R33: 19187 | S33: 52 | T33: 16+ Years | U33: 3810 CLEARWATER DR | W33: COLLEGE PARK | X33: GA | Y33: 30349
A34: =TRIM(D34) -> abravar | B34: 11024201831 | C34: BRAVAR,ALEX | D34: abravar | E34: A | F34: HS2023 | G34: Service Technician 2, In-Home | H34: In Home Tech | I34: TSH | J34: 58850 | K34: 08175 | L34: 28121 | M34: Richmond | N34: VA | O34: 42065 | P34: 44250 | Q34: 44250 | R34: 1679 | S34: 4 | T34: 3-6 Years | U34: 5902 Riviera Arch | W34: VIRGINIA BEACH | X34: VA | Y34: 23464
A35: =TRIM(D35) -> abrook0 | B35: 41024626434 | C35: BROOKS,ADONIS | D35: abrook0 | E35: A | F35: UHS003 | G35: Service Technician 2, In-Home | H35: In Home Tech | I35: TSH | J35: 58850 | K35: 08309 | L35: 08309 | M35: Clinton Township | N35: MI | O35: 45032 | P35: 45032 | Q35: 45032 | R35: 897 | S35: 2 | T35: 1-3 Years | U35: 2679 HARDING | W35: DETROIT | X35: MI | Y35: 48214
A36: =TRIM(D36) -> abrown0 | B36: 61024630746 | C36: BROWN,ADRIELLE | D36: abrown0 | E36: A | F36: HS2003 | G36: Service Technician 1, In-Home | H36: In Home Tech | I36: TSH | J36: 58890 | K36: 08206 | L36: 28129 | M36: Nashville | N36: TN | O36: 45823 | P36: 45823 | Q36: 45823 | R36: 106 | S36: 0 | T36: 91 Days - 6 Months | U36: 16255 Rio Grande St | W36: GULFPORT | X36: MS | Y36: 39501
A37: =TRIM(D37) -> abroyle | B37: 81024630488 | C37: BROYLES,ANDREW J | D37: abroyle | E37: T | F37: HS9661 | G37: Service Technician 3, In-Home | H37: In Home Tech | I37: TSH | J37: 58890 | K37: 08206 | L37: 28129 | M37: Nashville | N37: TN | O37: 45718 | P37: 45718 | Q37: 45718 | R37: 211 | S37: 0 | T37: 6 Mo - 1 Year | U37: 910 ROBIN HOOD DR. NW | W37: CLEVELAND | X37: TN | Y37: 37312
A38: =TRIM(D38) -> abyrd0 | B38: 61024631076 | C38: BYRD,ALFONSO E | D38: abyrd0 | E38: A | F38: HS2308 | G38: HVAC Svc Tech I, Break/Fix | H38: HVAC Tech | I38: TSH | J38: 58850 | K38: 08035 | L38: 28085 | M38: College Park | N38: GA | O38: 45914 | P38: 45914 | Q38: 45914 | R38: 15 | S38: 0 | T38: 0-30 Days | U38: 1048 FLAT SHOALS RD APT#1504 | V38: 1504 | W38: COLLEGE PARK | X38: GA | Y38: 30349
A39: =TRIM(D39) -> acadet | B39: 81024631128 | C39: Cadet,Adler | D39: acadet | E39: A | F39: HS2305 | G39: HVAC Svc Tech II, Break/Fix | H39: HVAC Tech | I39: TSH | J39: 58850 | K39: 07744 | L39: 28012 | M39: Melville | N39: NY | O39: 45907 | P39: 45907 | Q39: 45907 | R39: 22 | S39: 0 | T39: 0-30 Days | U39: 174-11 142nd | W39: Jamaica | X39: NY | Y39: 11434
A40: =TRIM(D40) -> ACANAL2 | B40: 01021063760 | C40: CANALES REYES,ADRIAN | D40: ACANAL2 | E40: A | F40: HS2023 | G40: Service Technician 2, In-Home | H40: In Home Tech | I40: PST | J40: 58850 | K40: 08935 | L40: 08935 | M40: San Juan | N40: PR | O40: 32560 | P40: 32560 | Q40: 32560 | R40: 13369 | S40: 36 | T40: 16+ Years | U40: #11 ANTONIO RODRIGUEZ ST. | W40: CATANO | X40: PR | Y40: 00962
...

Sheet TEST
A1: Date of this request | B1: Van Rental PO is opened up on in Holman | C1: Name | D1: Enterprise ID | E1: Trim Van Num | F1: Tech Ph Num | G1: Van assigned in TPMS | H1: Start Rental Date | I1: Repair Location | J1: ISSUE: | K1: Permanent Solution in place: | L1: AMS updated:
A2: 46090 | B2: 61263 | C2: MORGAN, TYLER | D2: JMORGA1 | E2: =TRIM(B2) -> 61263 | F2: 9106029707 | G2: =IFERROR(VLOOKUP(D2,'TPMS-auto'!A:J,6,0),"Not-in-TPMS") -> 088047 | H2: New Rental | I2: FIRESTONE, 7717 STATE AVE, KANSAS CITY, KS 66112 | J2: CHECK ENGINE LIGHT IS ON | K2: Repair van | L2: Yes

Sheet Rental Approvals 
A1: Date of this request | B1: Van Rental PO is opened up on in Holman | C1: Name | D1: Enterprise ID | E1: Trim Van Num | F1: Tech Ph Num | G1: Van assigned in TPMS | H1: Start Rental Date | I1: Repair Location | J1: ISSUE: | K1: Permanent Solution in place: | L1: AMS updated: | M1: Fleet Tracker Updated | N1: Rental Approved | O1: Approved in Holman | P1: Unit Number | Q1: Team Members | R1: Existing RENTAL opened on truck # | S1: New Rental or Extension | T1: Truck Breakdown or New Hire | U1: Existing Rental open for How long? | V1: Tech Service Date
A2: 45918 | B2: 46634 | C2: MCKENZIE, ANTHONY | D2: AMCKENZ | E2: =TRIM(B2) -> 46634 | F2: =IFERROR(VLOOKUP(D2,'TPMS-auto'!A:J, 10,0), "Not-in-TPMS") -> Not-in-TPMS | G2: =IFERROR(VLOOKUP(D2,'TPMS-auto'!A:J,6,0),"Not-in-TPMS") -> Not-in-TPMS | H2: 45887 | I2: Van 46634 looks like it is ready to go - located at: NH A MCKENZIE JR PEP BOYS 17050 NW 57TH AVE | J2: No van assigned in TPMS; Tech is in rental | K2: Assign van in TPMS - | L2: Yes | N2: No | O2: Yes | P2: =IFERROR(VLOOKUP(D2,'TPMS-auto'!A:D, 4,0),"Not-in-TPMS") -> Not-in-TPMS | Q2: =IFERROR(VLOOKUP(Table2[[#This Row],[Unit Number]],Ops,3,0),"Not-in-TPMS") -> Not-in-TPMS | R2: =IFERROR(VLOOKUP(Table2[[#This Row],[Enterprise ID]], 'ExistingRental-12.11'!A:H, 3, 0), "Not Open On 12.11") -> Not Open On 12.11 | S2: =IF(Table2[[#This Row],[Start Rental Date]]="New Rental", "New Rental", "Rental Extension Request") -> Rental Extension Request | T2: =IFERROR(IF(Table2[[#This Row],[Date of this request]]-Table2[[#This Row],[Tech Service Date]]<60, "New Hire Rental", "Truck Breakdown"), "New Hire Rental") -> New Hire Rental | U2: =IFERROR(VLOOKUP(Table2[[#This Row],[Enterprise ID]], 'ExistingRental-12.11'!A:H, 7, 0), "Not Open On 12.11") -> Not Open On 12.11 | V2: =IFERROR(VLOOKUP(Table2[[#This Row],[Enterprise ID]],'Tech-ServiceDate'!A:B,2,0), "EitherNewHire or Termed") -> EitherNewHire or Termed
A3: 45918 | B3: 46146 | C3: Dilan Abreu | D3: DABREU | E3: =TRIM(B3) -> 46146 | F3: =IFERROR(VLOOKUP(D3,'TPMS-auto'!A:J, 10,0), "Not-in-TPMS") -> 7735520093 | G3: =IFERROR(VLOOKUP(D3,'TPMS-auto'!A:J,6,0),"Not-in-TPMS") -> 021159 | H3: 45911 | I3: New hire - Truck is assigned in TPMS - was moved to Tulsa Ok - 907 NORTH F STREET, MUSKOGEE, OK, 74403 - this is RFARRO house - Samsara shows this van is there also | K3: 46146 has been moved to OK - need another van for this new hire tech | L3: Yes | N3: Yes | O3: Yes | P3: =IFERROR(VLOOKUP(D3,'TPMS-auto'!A:D, 4,0),"Not-in-TPMS") -> 0008555 | Q3: =IFERROR(VLOOKUP(Table2[[#This Row],[Unit Number]],Ops,3,0),"Not-in-TPMS") -> Monica, Cheryl & Machell | R3: =IFERROR(VLOOKUP(Table2[[#This Row],[Enterprise ID]], 'ExistingRental-12.11'!A:H, 3, 0), "Not Open On 12.11") -> Not Open On 12.11 | S3: =IF(Table2[[#This Row],[Start Rental Date]]="New Rental", "New Rental", "Rental Extension Request") -> Rental Extension Request | T3: =IFERROR(IF(Table2[[#This Row],[Date of this request]]-Table2[[#This Row],[Tech Service Date]]<60, "New Hire Rental", "Truck Breakdown"), "New Hire Rental") -> New Hire Rental | U3: =IFERROR(VLOOKUP(Table2[[#This Row],[Enterprise ID]], 'ExistingRental-12.11'!A:H, 7, 0), "Not Open On 12.11") -> Not Open On 12.11 | V3: =IFERROR(VLOOKUP(Table2[[#This Row],[Enterprise ID]],'Tech-ServiceDate'!A:B,2,0), "EitherNewHire or Termed") -> 45900
A4: 45918 | B4: 61679 | C4: JUAREZ, ELIJAH | D4: EJUAREZ | E4: =TRIM(B4) -> 61679 | F4: =IFERROR(VLOOKUP(D4,'TPMS-auto'!A:J, 10,0), "Not-in-TPMS") -> 9154330595 | G4: =IFERROR(VLOOKUP(D4,'TPMS-auto'!A:J,6,0),"Not-in-TPMS") -> 061679 | H4: 45898 | I4: AAMCO TOTAL CAR CARE 1407 LOMALAND DR #102 EL PASO TX 79935 | J4: Rear Diff on order will arrive 10/28 | K4: Rob Anderson: WHY is tech in a rental when van was approved for repair 8/29. Transmission slipping PO was voided - is this actually a declined repair?? this is actually a rear diff that is on order expected delivery date is 10/28 | L4: Yes | N4: Yes | O4: Yes | P4: =IFERROR(VLOOKUP(D4,'TPMS-auto'!A:D, 4,0),"Not-in-TPMS") -> 0008147 | Q4: =IFERROR(VLOOKUP(Table2[[#This Row],[Unit Number]],Ops,3,0),"Not-in-TPMS") -> Carol & Tasha | R4: =IFERROR(VLOOKUP(Table2[[#This Row],[Enterprise ID]], 'ExistingRental-12.11'!A:H, 3, 0), "Not Open On 12.11") -> 45993 | S4: =IF(Table2[[#This Row],[Start Rental Date]]="New Rental", "New Rental", "Rental Extension Request") -> Rental Extension Request | T4: =IFERROR(IF(Table2[[#This Row],[Date of this request]]-Table2[[#This Row],[Tech Service Date]]<60, "New Hire Rental", "Truck Breakdown"), "New Hire Rental") -> Truck Breakdown | U4: =IFERROR(VLOOKUP(Table2[[#This Row],[Enterprise ID]], 'ExistingRental-12.11'!A:H, 7, 0), "Not Open On 12.11") -> ELIJAH JUAREZ | V4: =IFERROR(VLOOKUP(Table2[[#This Row],[Enterprise ID]],'Tech-ServiceDate'!A:B,2,0), "EitherNewHire or Termed") -> 44805
A5: 45918 | B5: 36108 | C5: GOMEZ, JOHN | D5: JGOMEZ | E5: =TRIM(B5) -> 36108 | F5: =IFERROR(VLOOKUP(D5,'TPMS-auto'!A:J, 10,0), "Not-in-TPMS") -> Not-in-TPMS | G5: =IFERROR(VLOOKUP(D5,'TPMS-auto'!A:J,6,0),"Not-in-TPMS") -> Not-in-TPMS | H5: New Rental | I5: Rental - JGOMEZ in rental - Van location is unknown - need to find out where this van is - no PO open in Holman except for the rental PO (Last known location is: 12392 EASTLINE ROAD, TRENTON, TX, 75490) | J5: Tech does not have a permanent van assignment - this truck was used as a random truck assignment- Tech needs a permanent van | K5: Find a permanent van for this tech | L5: Yes | N5: Yes | O5: Yes | P5: =IFERROR(VLOOKUP(D5,'TPMS-auto'!A:D, 4,0),"Not-in-TPMS") -> Not-in-TPMS | Q5: =IFERROR(VLOOKUP(Table2[[#This Row],[Unit Number]],Ops,3,0),"Not-in-TPMS") -> Not-in-TPMS | R5: =IFERROR(VLOOKUP(Table2[[#This Row],[Enterprise ID]], 'ExistingRental-12.11'!A:H, 3, 0), "Not Open On 12.11") -> Not Open On 12.11 | S5: =IF(Table2[[#This Row],[Start Rental Date]]="New Rental", "New Rental", "Rental Extension Request") -> New Rental | T5: =IFERROR(IF(Table2[[#This Row],[Date of this request]]-Table2[[#This Row],[Tech Service Date]]<60, "New Hire Rental", "Truck Breakdown"), "New Hire Rental") -> New Hire Rental | U5: =IFERROR(VLOOKUP(Table2[[#This Row],[Enterprise ID]], 'ExistingRental-12.11'!A:H, 7, 0), "Not Open On 12.11") -> Not Open On 12.11 | V5: =IFERROR(VLOOKUP(Table2[[#This Row],[Enterprise ID]],'Tech-ServiceDate'!A:B,2,0), "EitherNewHire or Termed") -> EitherNewHire or Termed
A6: 45918 | B6: 21091 | C6: JOHNNY QUACH | D6: JQUACH | E6: =TRIM(B6) -> 21091 | F6: =IFERROR(VLOOKUP(D6,'TPMS-auto'!A:J, 10,0), "Not-in-TPMS") -> 6262032405 | G6: =IFERROR(VLOOKUP(D6,'TPMS-auto'!A:J,6,0),"Not-in-TPMS") -> 021091 | I6: PEP BOYS 11937 E VALLEY BLVD EL MONTE CA 91732 | J6: PO approved on 9/16 - | K6: Tech JQUACH in rental 9/16 - PO approved 9/17 - rental extended 9/18 - tire only repair - get out of the shop asap | L6: Yes | N6: Yes | O6: Yes | P6: =IFERROR(VLOOKUP(D6,'TPMS-auto'!A:D, 4,0),"Not-in-TPMS") -> 0007108 | Q6: =IFERROR(VLOOKUP(Table2[[#This Row],[Unit Number]],Ops,3,0),"Not-in-TPMS") -> Carol & Tasha | R6: =IFERROR(VLOOKUP(Table2[[#This Row],[Enterprise ID]], 'ExistingRental-12.11'!A:H, 3, 0), "Not Open On 12.11") -> Not Open On 12.11 | S6: =IF(Table2[[#This Row],[Start Rental Date]]="New Rental", "New Rental", "Rental Extension Request") -> Rental Extension Request | T6: =IFERROR(IF(Table2[[#This Row],[Date of this request]]-Table2[[#This Row],[Tech Service Date]]<60, "New Hire Rental", "Truck Breakdown"), "New Hire Rental") -> Truck Breakdown | U6: =IFERROR(VLOOKUP(Table2[[#This Row],[Enterprise ID]], 'ExistingRental-12.11'!A:H, 7, 0), "Not Open On 12.11") -> Not Open On 12.11 | V6: =IFERROR(VLOOKUP(Table2[[#This Row],[Enterprise ID]],'Tech-ServiceDate'!A:B,2,0), "EitherNewHire or Termed") -> 40785
A7: 45918 | B7: 46835 | C7: HARTLEY, JONATHAN | D7: JHARTLE | E7: =TRIM(B7) -> 46835 | F7: =IFERROR(VLOOKUP(D7,'TPMS-auto'!A:J, 10,0), "Not-in-TPMS") -> 8287230074 | G7: =IFERROR(VLOOKUP(D7,'TPMS-auto'!A:J,6,0),"Not-in-TPMS") -> 046835 | I7: DALE EARNHART CHEVROLET, PO BOX 1250, NEWTON NC 28658 - no estimate since 8/27 | J7: Tech in rental - repair at Chevrolet - has no estimate to approve | K7: Get van repaired and tech out of rental | L7: Yes | N7: Yes | O7: Yes | P7: =IFERROR(VLOOKUP(D7,'TPMS-auto'!A:D, 4,0),"Not-in-TPMS") -> 0004766 | Q7: =IFERROR(VLOOKUP(Table2[[#This Row],[Unit Number]],Ops,3,0),"Not-in-TPMS") -> Rob & Andrea | R7: =IFERROR(VLOOKUP(Table2[[#This Row],[Enterprise ID]], 'ExistingRental-12.11'!A:H, 3, 0), "Not Open On 12.11") -> Not Open On 12.11 | S7: =IF(Table2[[#This Row],[Start Rental Date]]="New Rental", "New Rental", "Rental Extension Request") -> Rental Extension Request | T7: =IFERROR(IF(Table2[[#This Row],[Date of this request]]-Table2[[#This Row],[Tech Service Date]]<60, "New Hire Rental", "Truck Breakdown"), "New Hire Rental") -> Truck Breakdown | U7: =IFERROR(VLOOKUP(Table2[[#This Row],[Enterprise ID]], 'ExistingRental-12.11'!A:H, 7, 0), "Not Open On 12.11") -> Not Open On 12.11 | V7: =IFERROR(VLOOKUP(Table2[[#This Row],[Enterprise ID]],'Tech-ServiceDate'!A:B,2,0), "EitherNewHire or Termed") -> 45501
A8: 45918 | B8: 36161 | C8: GREGORY, KENTREL | D8: KGREGOR | E8: =TRIM(B8) -> 36161 | F8: =IFERROR(VLOOKUP(D8,'TPMS-auto'!A:J, 10,0), "Not-in-TPMS") -> 5028302709 | G8: =IFERROR(VLOOKUP(D8,'TPMS-auto'!A:J,6,0),"Not-in-TPMS") -> 036161 | H8: 45909 | I8: Rental extension request - van is repaired and is at: PEP BOYS, 1001 BRECKENRIDGE LN, LOUISVILLE KY 40207 | K8: 36161 needs to be assigned to this tech and he needs to pick up the van | L8: Yes | N8: No - go get the van at PEP BOYS, 1001 BRECKENRIDGE LN, LOUISVILLE KY 40207 | O8: Yes | P8: =IFERROR(VLOOKUP(D8,'TPMS-auto'!A:D, 4,0),"Not-in-TPMS") -> 0004766 | Q8: =IFERROR(VLOOKUP(Table2[[#This Row],[Unit Number]],Ops,3,0),"Not-in-TPMS") -> Rob & Andrea | R8: =IFERROR(VLOOKUP(Table2[[#This Row],[Enterprise ID]], 'ExistingRental-12.11'!A:H, 3, 0), "Not Open On 12.11") -> Not Open On 12.11 | S8: =IF(Table2[[#This Row],[Start Rental Date]]="New Rental", "New Rental", "Rental Extension Request") -> Rental Extension Request | T8: =IFERROR(IF(Table2[[#This Row],[Date of this request]]-Table2[[#This Row],[Tech Service Date]]<60, "New Hire Rental", "Truck Breakdown"), "New Hire Rental") -> New Hire Rental | U8: =IFERROR(VLOOKUP(Table2[[#This Row],[Enterprise ID]], 'ExistingRental-12.11'!A:H, 7, 0), "Not Open On 12.11") -> Not Open On 12.11 | V8: =IFERROR(VLOOKUP(Table2[[#This Row],[Enterprise ID]],'Tech-ServiceDate'!A:B,2,0), "EitherNewHire or Termed") -> 45893
A9: 45918 | B9: 36003 | C9: Fazil Hamza | D9: FHAMZA | E9: =TRIM(B9) -> 36003 | F9: =IFERROR(VLOOKUP(D9,'TPMS-auto'!A:J, 10,0), "Not-in-TPMS") -> 7323185436 | G9: =IFERROR(VLOOKUP(D9,'TPMS-auto'!A:J,6,0),"Not-in-TPMS") -> 046509 | H9: 45838 | I9: Van was approved for major repair on 2.20.2025. Need repair status LINDSAY CHEVROLET INC, 15605 JEFFERSON DAVIS HWY, WOODBRIDGE VA 22191 | J9: Last PO approval was 4687.45 on 8/28 0 need final repair status | K9: Tech to get 46509 back to him and release 36003 for another tech | L9: Yes | N9: Yes | O9: Yes | P9: =IFERROR(VLOOKUP(D9,'TPMS-auto'!A:D, 4,0),"Not-in-TPMS") -> 0007084 | Q9: =IFERROR(VLOOKUP(Table2[[#This Row],[Unit Number]],Ops,3,0),"Not-in-TPMS") -> Monica, Cheryl & Machell | R9: =IFERROR(VLOOKUP(Table2[[#This Row],[Enterprise ID]], 'ExistingRental-12.11'!A:H, 3, 0), "Not Open On 12.11") -> 45992 | S9: =IF(Table2[[#This Row],[Start Rental Date]]="New Rental", "New Rental", "Rental Extension Request") -> Rental Extension Request | T9: =IFERROR(IF(Table2[[#This Row],[Date of this request]]-Table2[[#This Row],[Tech Service Date]]<60, "New Hire Rental", "Truck Breakdown"), "New Hire Rental") -> Truck Breakdown | U9: =IFERROR(VLOOKUP(Table2[[#This Row],[Enterprise ID]], 'ExistingRental-12.11'!A:H, 7, 0), "Not Open On 12.11") -> FAZIL HAMZA | V9: =IFERROR(VLOOKUP(Table2[[#This Row],[Enterprise ID]],'Tech-ServiceDate'!A:B,2,0), "EitherNewHire or Termed") -> 44209
A10: 45918 | B10: 47164 | C10: Alan Hollis | D10: AHOLLIS | E10: =TRIM(B10) -> 47164 | F10: =IFERROR(VLOOKUP(D10,'TPMS-auto'!A:J, 10,0), "Not-in-TPMS") -> 7064020229 | G10: =IFERROR(VLOOKUP(D10,'TPMS-auto'!A:J,6,0),"Not-in-TPMS") -> 046702 | H10: 45849 | I10: This is not assigned to this tech - he's getting 46702? | J10: Last service PO is in Pepboys - repaired on 5/30 | K10: Assign truck 46702 in TPMS | L10: Yes | N10: No | O10: Yes | P10: =IFERROR(VLOOKUP(D10,'TPMS-auto'!A:D, 4,0),"Not-in-TPMS") -> 0008035 | Q10: =IFERROR(VLOOKUP(Table2[[#This Row],[Unit Number]],Ops,3,0),"Not-in-TPMS") -> Rob & Andrea | R10: =IFERROR(VLOOKUP(Table2[[#This Row],[Enterprise ID]], 'ExistingRental-12.11'!A:H, 3, 0), "Not Open On 12.11") -> Not Open On 12.11 | S10: =IF(Table2[[#This Row],[Start Rental Date]]="New Rental", "New Rental", "Rental Extension Request") -> Rental Extension Request | T10: =IFERROR(IF(Table2[[#This Row],[Date of this request]]-Table2[[#This Row],[Tech Service Date]]<60, "New Hire Rental", "Truck Breakdown"), "New Hire Rental") -> Truck Breakdown | U10: =IFERROR(VLOOKUP(Table2[[#This Row],[Enterprise ID]], 'ExistingRental-12.11'!A:H, 7, 0), "Not Open On 12.11") -> Not Open On 12.11 | V10: =IFERROR(VLOOKUP(Table2[[#This Row],[Enterprise ID]],'Tech-ServiceDate'!A:B,2,0), "EitherNewHire or Termed") -> 45844
A11: 45918 | B11: 21187 | C11: London Williams | D11: LWILLI3 | E11: =TRIM(B11) -> 21187 | F11: =IFERROR(VLOOKUP(D11,'TPMS-auto'!A:J, 10,0), "Not-in-TPMS") -> 2253371244 | G11: =IFERROR(VLOOKUP(D11,'TPMS-auto'!A:J,6,0),"Not-in-TPMS") -> 023686 | H11: New Rental | I11: AMS showed van was at PEP BOYS 12200 I-10 SERVICE RD , NEW ORLEANS, LA, 70128 for 2nd opinion- Banner Chevrolet kept the van for a long time and didn't repair - New info says van is at Otter Self Storage - 9425 Burbank Dr, Baton Rouge, LA 70810 | J11: Tech assigned van 23686, but has 21187 listed as rental. 21187 is at Pep Boys for 2nd opinion - | K11: No - needs a permanent van replacement - neither van is a good option (21187 nor 23686) | L11: Yes | N11: Yes | O11: Yes | P11: =IFERROR(VLOOKUP(D11,'TPMS-auto'!A:D, 4,0),"Not-in-TPMS") -> 0008206 | Q11: =IFERROR(VLOOKUP(Table2[[#This Row],[Unit Number]],Ops,3,0),"Not-in-TPMS") -> Monica, Cheryl & Machell | R11: =IFERROR(VLOOKUP(Table2[[#This Row],[Enterprise ID]], 'ExistingRental-12.11'!A:H, 3, 0), "Not Open On 12.11") -> Not Open On 12.11 | S11: =IF(Table2[[#This Row],[Start Rental Date]]="New Rental", "New Rental", "Rental Extension Request") -> New Rental | T11: =IFERROR(IF(Table2[[#This Row],[Date of this request]]-Table2[[#This Row],[Tech Service Date]]<60, "New Hire Rental", "Truck Breakdown"), "New Hire Rental") -> Truck Breakdown | U11: =IFERROR(VLOOKUP(Table2[[#This Row],[Enterprise ID]], 'ExistingRental-12.11'!A:H, 7, 0), "Not Open On 12.11") -> Not Open On 12.11 | V11: =IFERROR(VLOOKUP(Table2[[#This Row],[Enterprise ID]],'Tech-ServiceDate'!A:B,2,0), "EitherNewHire or Termed") -> 45816
A12: 45918 | B12: 22234 | C12: Jonathan Washabaugh | D12: JWASHAB | E12: =TRIM(B12) -> 22234 | F12: =IFERROR(VLOOKUP(D12,'TPMS-auto'!A:J, 10,0), "Not-in-TPMS") -> 8599131963 | G12: =IFERROR(VLOOKUP(D12,'TPMS-auto'!A:J,6,0),"Not-in-TPMS") -> 037176 | H12: 45915 | I12: Tech in rental - 9/12 - at AAMCO - needs repair and get back to the tech | K12: Get estimate and get repaired at AAMCO | L12: Yes | N12: Yes | O12: Yes | P12: =IFERROR(VLOOKUP(D12,'TPMS-auto'!A:D, 4,0),"Not-in-TPMS") -> 0004766 | Q12: =IFERROR(VLOOKUP(Table2[[#This Row],[Unit Number]],Ops,3,0),"Not-in-TPMS") -> Rob & Andrea | R12: =IFERROR(VLOOKUP(Table2[[#This Row],[Enterprise ID]], 'ExistingRental-12.11'!A:H, 3, 0), "Not Open On 12.11") -> Not Open On 12.11 | S12: =IF(Table2[[#This Row],[Start Rental Date]]="New Rental", "New Rental", "Rental Extension Request") -> Rental Extension Request | T12: =IFERROR(IF(Table2[[#This Row],[Date of this request]]-Table2[[#This Row],[Tech Service Date]]<60, "New Hire Rental", "Truck Breakdown"), "New Hire Rental") -> Truck Breakdown | U12: =IFERROR(VLOOKUP(Table2[[#This Row],[Enterprise ID]], 'ExistingRental-12.11'!A:H, 7, 0), "Not Open On 12.11") -> Not Open On 12.11 | V12: =IFERROR(VLOOKUP(Table2[[#This Row],[Enterprise ID]],'Tech-ServiceDate'!A:B,2,0), "EitherNewHire or Termed") -> 44686
A13: 45918 | B13: 37125 | C13: Kareem Williams | D13: KWILLI1 | E13: =TRIM(B13) -> 37125 | F13: =IFERROR(VLOOKUP(D13,'TPMS-auto'!A:J, 10,0), "Not-in-TPMS") -> 2287602794 | G13: =IFERROR(VLOOKUP(D13,'TPMS-auto'!A:J,6,0),"Not-in-TPMS") -> 037125 | H13: 45910 | I13: New hire - 9/2 start, 9/23 on route - need to set up transportation to get the tech and van connected - no OPEN pos on 37125 | J13: No van assigned in TPMS; Tech is in rental | K13: Get him a permanent van asap - van is in Laurel, MS - going to Gulfport, MS - | L13: Yes | N13: Yes | O13: Yes | P13: =IFERROR(VLOOKUP(D13,'TPMS-auto'!A:D, 4,0),"Not-in-TPMS") -> 0008206 | Q13: =IFERROR(VLOOKUP(Table2[[#This Row],[Unit Number]],Ops,3,0),"Not-in-TPMS") -> Monica, Cheryl & Machell | R13: =IFERROR(VLOOKUP(Table2[[#This Row],[Enterprise ID]], 'ExistingRental-12.11'!A:H, 3, 0), "Not Open On 12.11") -> 45971 | S13: =IF(Table2[[#This Row],[Start Rental Date]]="New Rental", "New Rental", "Rental Extension Request") -> Rental Extension Request | T13: =IFERROR(IF(Table2[[#This Row],[Date of this request]]-Table2[[#This Row],[Tech Service Date]]<60, "New Hire Rental", "Truck Breakdown"), "New Hire Rental") -> New Hire Rental | U13: =IFERROR(VLOOKUP(Table2[[#This Row],[Enterprise ID]], 'ExistingRental-12.11'!A:H, 7, 0), "Not Open On 12.11") -> KAREEM WILLIAMS | V13: =IFERROR(VLOOKUP(Table2[[#This Row],[Enterprise ID]],'Tech-ServiceDate'!A:B,2,0), "EitherNewHire or Termed") -> 45900
A14: 45918 | B14: 61470 | C14: LARSON, CHRISTOPHER | D14: CLARSON | E14: =TRIM(B14) -> 61470 | F14: =IFERROR(VLOOKUP(D14,'TPMS-auto'!A:J, 10,0), "Not-in-TPMS") -> 6605001207 | G14: =IFERROR(VLOOKUP(D14,'TPMS-auto'!A:J,6,0),"Not-in-TPMS") -> 046161 | H14: 45896 | I14: Declined repair - after 2nd estimate - $9,794.76 - need permanent van assignment | K14: Van will be declined repair $9,794.76 - need a permanent van assignment | L14: Yes | N14: Yes | O14: Yes | P14: =IFERROR(VLOOKUP(D14,'TPMS-auto'!A:D, 4,0),"Not-in-TPMS") -> 0008420 | Q14: =IFERROR(VLOOKUP(Table2[[#This Row],[Unit Number]],Ops,3,0),"Not-in-TPMS") -> Rob & Andrea | R14: =IFERROR(VLOOKUP(Table2[[#This Row],[Enterprise ID]], 'ExistingRental-12.11'!A:H, 3, 0), "Not Open On 12.11") -> Not Open On 12.11 | S14: =IF(Table2[[#This Row],[Start Rental Date]]="New Rental", "New Rental", "Rental Extension Request") -> Rental Extension Request | T14: =IFERROR(IF(Table2[[#This Row],[Date of this request]]-Table2[[#This Row],[Tech Service Date]]<60, "New Hire Rental", "Truck Breakdown"), "New Hire Rental") -> Truck Breakdown | U14: =IFERROR(VLOOKUP(Table2[[#This Row],[Enterprise ID]], 'ExistingRental-12.11'!A:H, 7, 0), "Not Open On 12.11") -> Not Open On 12.11 | V14: =IFERROR(VLOOKUP(Table2[[#This Row],[Enterprise ID]],'Tech-ServiceDate'!A:B,2,0), "EitherNewHire or Termed") -> 44307
A15: 45918 | B15: 61015 | C15: SOKOLOWSKI, BERNARD | D15: BSOKOLO | E15: =TRIM(B15) -> 61015 | F15: =IFERROR(VLOOKUP(D15,'TPMS-auto'!A:J, 10,0), "Not-in-TPMS") -> 7249536540 | G15: =IFERROR(VLOOKUP(D15,'TPMS-auto'!A:J,6,0),"Not-in-TPMS") -> 061016 | H15: 45862 | I15: Tech in rental since 7/24 - is the van here: PEP BOYS 20229 ROUTE 19, CRANBERRY TWP, PA, 16066 | J15: Where is this van? Tech rental on 7/24 but no repair scheduled | K15: Find van, get repair estimate | L15: Yes | N15: Yes | O15: Yes | P15: =IFERROR(VLOOKUP(D15,'TPMS-auto'!A:D, 4,0),"Not-in-TPMS") -> 0004766 | Q15: =IFERROR(VLOOKUP(Table2[[#This Row],[Unit Number]],Ops,3,0),"Not-in-TPMS") -> Rob & Andrea | R15: =IFERROR(VLOOKUP(Table2[[#This Row],[Enterprise ID]], 'ExistingRental-12.11'!A:H, 3, 0), "Not Open On 12.11") -> Not Open On 12.11 | S15: =IF(Table2[[#This Row],[Start Rental Date]]="New Rental", "New Rental", "Rental Extension Request") -> Rental Extension Request | T15: =IFERROR(IF(Table2[[#This Row],[Date of this request]]-Table2[[#This Row],[Tech Service Date]]<60, "New Hire Rental", "Truck Breakdown"), "New Hire Rental") -> Truck Breakdown | U15: =IFERROR(VLOOKUP(Table2[[#This Row],[Enterprise ID]], 'ExistingRental-12.11'!A:H, 7, 0), "Not Open On 12.11") -> Not Open On 12.11 | V15: =IFERROR(VLOOKUP(Table2[[#This Row],[Enterprise ID]],'Tech-ServiceDate'!A:B,2,0), "EitherNewHire or Termed") -> 37255
A16: 45918 | B16: 36222 | C16: COMBS, GRANT | D16: GCOMBS | E16: =TRIM(B16) -> 36222 | F16: =IFERROR(VLOOKUP(D16,'TPMS-auto'!A:J, 10,0), "Not-in-TPMS") -> Not-in-TPMS | G16: =IFERROR(VLOOKUP(D16,'TPMS-auto'!A:J,6,0),"Not-in-TPMS") -> Not-in-TPMS | H16: 45828 | I16: Needs a windshield - approved on 9/15 in Holman - Safelite | J16: Tech in rental since 6/20; What is the scheduled date for the windshield? | K16: Tech in rental since 6/20- getting 61354 - just need windshield replaced and get tech out of rental into the van | L16: Yes | N16: Yes | O16: Yes | P16: =IFERROR(VLOOKUP(D16,'TPMS-auto'!A:D, 4,0),"Not-in-TPMS") -> Not-in-TPMS | Q16: =IFERROR(VLOOKUP(Table2[[#This Row],[Unit Number]],Ops,3,0),"Not-in-TPMS") -> Not-in-TPMS | R16: =IFERROR(VLOOKUP(Table2[[#This Row],[Enterprise ID]], 'ExistingRental-12.11'!A:H, 3, 0), "Not Open On 12.11") -> Not Open On 12.11 | S16: =IF(Table2[[#This Row],[Start Rental Date]]="New Rental", "New Rental", "Rental Extension Request") -> Rental Extension Request | T16: =IFERROR(IF(Table2[[#This Row],[Date of this request]]-Table2[[#This Row],[Tech Service Date]]<60, "New Hire Rental", "Truck Breakdown"), "New Hire Rental") -> New Hire Rental | U16: =IFERROR(VLOOKUP(Table2[[#This Row],[Enterprise ID]], 'ExistingRental-12.11'!A:H, 7, 0), "Not Open On 12.11") -> Not Open On 12.11 | V16: =IFERROR(VLOOKUP(Table2[[#This Row],[Enterprise ID]],'Tech-ServiceDate'!A:B,2,0), "EitherNewHire or Termed") -> EitherNewHire or Termed
A17: 45918 | B17: 36305 | C17: Francis Grejdus | D17: FGREJDU | E17: =TRIM(B17) -> 36305 | F17: =IFERROR(VLOOKUP(D17,'TPMS-auto'!A:J, 10,0), "Not-in-TPMS") -> 8655009637 | G17: =IFERROR(VLOOKUP(D17,'TPMS-auto'!A:J,6,0),"Not-in-TPMS") -> 036305 | H17: 45918 | K17: Get van repaired and tech out of rental | L17: Yes | N17: Yes | O17: Yes | P17: =IFERROR(VLOOKUP(D17,'TPMS-auto'!A:D, 4,0),"Not-in-TPMS") -> 0004766 | Q17: =IFERROR(VLOOKUP(Table2[[#This Row],[Unit Number]],Ops,3,0),"Not-in-TPMS") -> Rob & Andrea | R17: =IFERROR(VLOOKUP(Table2[[#This Row],[Enterprise ID]], 'ExistingRental-12.11'!A:H, 3, 0), "Not Open On 12.11") -> Not Open On 12.11 | S17: =IF(Table2[[#This Row],[Start Rental Date]]="New Rental", "New Rental", "Rental Extension Request") -> Rental Extension Request | T17: =IFERROR(IF(Table2[[#This Row],[Date of this request]]-Table2[[#This Row],[Tech Service Date]]<60, "New Hire Rental", "Truck Breakdown"), "New Hire Rental") -> Truck Breakdown | U17: =IFERROR(VLOOKUP(Table2[[#This Row],[Enterprise ID]], 'ExistingRental-12.11'!A:H, 7, 0), "Not Open On 12.11") -> Not Open On 12.11 | V17: =IFERROR(VLOOKUP(Table2[[#This Row],[Enterprise ID]],'Tech-ServiceDate'!A:B,2,0), "EitherNewHire or Termed") -> 38744
A18: 45918 | B18: 23394 | C18: VELEZ, SUAMYS | D18: SVELEZ4 | E18: =TRIM(B18) -> 23394 | F18: =IFERROR(VLOOKUP(D18,'TPMS-auto'!A:J, 10,0), "Not-in-TPMS") -> Not-in-TPMS | G18: =IFERROR(VLOOKUP(D18,'TPMS-auto'!A:J,6,0),"Not-in-TPMS") -> Not-in-TPMS | H18: 45825 | I18: PEP BOYS, 1490 US 70 W, GARNER NC 27529 | K18: Get van repaired and tech out of rental | L18: Yes | N18: Yes | O18: Yes | P18: =IFERROR(VLOOKUP(D18,'TPMS-auto'!A:D, 4,0),"Not-in-TPMS") -> Not-in-TPMS | Q18: =IFERROR(VLOOKUP(Table2[[#This Row],[Unit Number]],Ops,3,0),"Not-in-TPMS") -> Not-in-TPMS | R18: =IFERROR(VLOOKUP(Table2[[#This Row],[Enterprise ID]], 'ExistingRental-12.11'!A:H, 3, 0), "Not Open On 12.11") -> Not Open On 12.11 | S18: =IF(Table2[[#This Row],[Start Rental Date]]="New Rental", "New Rental", "Rental Extension Request") -> Rental Extension Request | T18: =IFERROR(IF(Table2[[#This Row],[Date of this request]]-Table2[[#This Row],[Tech Service Date]]<60, "New Hire Rental", "Truck Breakdown"), "New Hire Rental") -> Truck Breakdown | U18: =IFERROR(VLOOKUP(Table2[[#This Row],[Enterprise ID]], 'ExistingRental-12.11'!A:H, 7, 0), "Not Open On 12.11") -> Not Open On 12.11 | V18: =IFERROR(VLOOKUP(Table2[[#This Row],[Enterprise ID]],'Tech-ServiceDate'!A:B,2,0), "EitherNewHire or Termed") -> 43263
A19: 45918 | B19: 46837 | C19: SAMMONS, ALEX | D19: ASAMMON | E19: =TRIM(B19) -> 46837 | F19: =IFERROR(VLOOKUP(D19,'TPMS-auto'!A:J, 10,0), "Not-in-TPMS") -> Not-in-TPMS | G19: =IFERROR(VLOOKUP(D19,'TPMS-auto'!A:J,6,0),"Not-in-TPMS") -> Not-in-TPMS | H19: 45903 | I19: New Hire - no permanent van assignement - Move van from: PEP BOYS, 215 BOARDMAN POLAND RD, BOARDMAN OH 44512 - to 5844 E. P Ridge Road Apt 6 Huntington, WV | J19: No van assigned in TPMS; Tech is in rental - van is in | K19: Assign this van to ASAMMON and schedule transportation to get the van to him | L19: Yes | N19: Yes | O19: Yes | P19: =IFERROR(VLOOKUP(D19,'TPMS-auto'!A:D, 4,0),"Not-in-TPMS") -> Not-in-TPMS | Q19: =IFERROR(VLOOKUP(Table2[[#This Row],[Unit Number]],Ops,3,0),"Not-in-TPMS") -> Not-in-TPMS | R19: =IFERROR(VLOOKUP(Table2[[#This Row],[Enterprise ID]], 'ExistingRental-12.11'!A:H, 3, 0), "Not Open On 12.11") -> Not Open On 12.11 | S19: =IF(Table2[[#This Row],[Start Rental Date]]="New Rental", "New Rental", "Rental Extension Request") -> Rental Extension Request | T19: =IFERROR(IF(Table2[[#This Row],[Date of this request]]-Table2[[#This Row],[Tech Service Date]]<60, "New Hire Rental", "Truck Breakdown"), "New Hire Rental") -> New Hire Rental | U19: =IFERROR(VLOOKUP(Table2[[#This Row],[Enterprise ID]], 'ExistingRental-12.11'!A:H, 7, 0), "Not Open On 12.11") -> Not Open On 12.11 | V19: =IFERROR(VLOOKUP(Table2[[#This Row],[Enterprise ID]],'Tech-ServiceDate'!A:B,2,0), "EitherNewHire or Termed") -> EitherNewHire or Termed
A20: 45918 | B20: 46209 | C20: Jorge Pena | D20: JPENA1 | E20: =TRIM(B20) -> 46209 | F20: =IFERROR(VLOOKUP(D20,'TPMS-auto'!A:J, 10,0), "Not-in-TPMS") -> 2109150317 | G20: =IFERROR(VLOOKUP(D20,'TPMS-auto'!A:J,6,0),"Not-in-TPMS") -> 046209 | H20: New Rental | I20: Tech in rental - JPENA1 - PO approved on 8/29 for AC repair - why is it still there? | J20: PO approved 8/29, tech asking for rental extension | K20: Get van repaired and tech out of rental | L20: Yes | N20: Yes | O20: Yes | P20: =IFERROR(VLOOKUP(D20,'TPMS-auto'!A:D, 4,0),"Not-in-TPMS") -> 0008147 | Q20: =IFERROR(VLOOKUP(Table2[[#This Row],[Unit Number]],Ops,3,0),"Not-in-TPMS") -> Carol & Tasha | R20: =IFERROR(VLOOKUP(Table2[[#This Row],[Enterprise ID]], 'ExistingRental-12.11'!A:H, 3, 0), "Not Open On 12.11") -> 45960 | S20: =IF(Table2[[#This Row],[Start Rental Date]]="New Rental", "New Rental", "Rental Extension Request") -> New Rental | T20: =IFERROR(IF(Table2[[#This Row],[Date of this request]]-Table2[[#This Row],[Tech Service Date]]<60, "New Hire Rental", "Truck Breakdown"), "New Hire Rental") -> Truck Breakdown | U20: =IFERROR(VLOOKUP(Table2[[#This Row],[Enterprise ID]], 'ExistingRental-12.11'!A:H, 7, 0), "Not Open On 12.11") -> JORGE PENA | V20: =IFERROR(VLOOKUP(Table2[[#This Row],[Enterprise ID]],'Tech-ServiceDate'!A:B,2,0), "EitherNewHire or Termed") -> 44980
A21: 45918 | B21: 61320 | C21: LE, SHYHEIM | D21: SPELLE | E21: =TRIM(B21) -> 61320 | F21: =IFERROR(VLOOKUP(D21,'TPMS-auto'!A:J, 10,0), "Not-in-TPMS") -> 4109821742 | G21: =IFERROR(VLOOKUP(D21,'TPMS-auto'!A:J,6,0),"Not-in-TPMS") -> 061320 | I21: Accident - truck is at: CHESAPEAKE SERVICE CENTER LLC, 895B NOTTINGHAM RD, ELKTON MD 21921 | K21: Send to body shop to get fixed | L21: Yes | N21: Yes | O21: Yes | P21: =IFERROR(VLOOKUP(D21,'TPMS-auto'!A:D, 4,0),"Not-in-TPMS") -> 0007084 | Q21: =IFERROR(VLOOKUP(Table2[[#This Row],[Unit Number]],Ops,3,0),"Not-in-TPMS") -> Monica, Cheryl & Machell | R21: =IFERROR(VLOOKUP(Table2[[#This Row],[Enterprise ID]], 'ExistingRental-12.11'!A:H, 3, 0), "Not Open On 12.11") -> 45877 | S21: =IF(Table2[[#This Row],[Start Rental Date]]="New Rental", "New Rental", "Rental Extension Request") -> Rental Extension Request | T21: =IFERROR(IF(Table2[[#This Row],[Date of this request]]-Table2[[#This Row],[Tech Service Date]]<60, "New Hire Rental", "Truck Breakdown"), "New Hire Rental") -> Truck Breakdown | U21: =IFERROR(VLOOKUP(Table2[[#This Row],[Enterprise ID]], 'ExistingRental-12.11'!A:H, 7, 0), "Not Open On 12.11") -> SHYHEIM PELLE | V21: =IFERROR(VLOOKUP(Table2[[#This Row],[Enterprise ID]],'Tech-ServiceDate'!A:B,2,0), "EitherNewHire or Termed") -> 45256
A22: 45918 | B22: 21689 | C22: Tyler Carnahan | D22: TCARNAH | E22: =TRIM(B22) -> 21689 | F22: =IFERROR(VLOOKUP(D22,'TPMS-auto'!A:J, 10,0), "Not-in-TPMS") -> 8136480860 | G22: =IFERROR(VLOOKUP(D22,'TPMS-auto'!A:J,6,0),"Not-in-TPMS") -> 021207 | H22: 45905 | I22: Van is at Expert Car Care - last location - 3016 ALAFAYA TRAIL, OVIEDO FL 32765 - Van is being driven daily | K22: Assign in TPMS - Van is at Expert Car Care or find the van where it is. | L22: Yes | N22: No | O22: Yes | P22: =IFERROR(VLOOKUP(D22,'TPMS-auto'!A:D, 4,0),"Not-in-TPMS") -> 0007435 | Q22: =IFERROR(VLOOKUP(Table2[[#This Row],[Unit Number]],Ops,3,0),"Not-in-TPMS") -> Rob & Andrea | R22: =IFERROR(VLOOKUP(Table2[[#This Row],[Enterprise ID]], 'ExistingRental-12.11'!A:H, 3, 0), "Not Open On 12.11") -> 45861 | S22: =IF(Table2[[#This Row],[Start Rental Date]]="New Rental", "New Rental", "Rental Extension Request") -> Rental Extension Request | T22: =IFERROR(IF(Table2[[#This Row],[Date of this request]]-Table2[[#This Row],[Tech Service Date]]<60, "New Hire Rental", "Truck Breakdown"), "New Hire Rental") -> New Hire Rental | U22: =IFERROR(VLOOKUP(Table2[[#This Row],[Enterprise ID]], 'ExistingRental-12.11'!A:H, 7, 0), "Not Open On 12.11") -> TYLER CARNAHAN | V22: =IFERROR(VLOOKUP(Table2[[#This Row],[Enterprise ID]],'Tech-ServiceDate'!A:B,2,0), "EitherNewHire or Termed") -> 45893
A23: 45918 | B23: 23862 | C23: COUCH, VAN | D23: VCOUCH | E23: =TRIM(B23) -> 23862 | F23: =IFERROR(VLOOKUP(D23,'TPMS-auto'!A:J, 10,0), "Not-in-TPMS") -> 3312407987 | G23: =IFERROR(VLOOKUP(D23,'TPMS-auto'!A:J,6,0),"Not-in-TPMS") -> 023862 | H23: 45876 | I23: Tech picked up and brought back on 9/5 - AC repair was at PEP BOYS, 17015 TORRENCE AVE, LANSING IL 60438 | K23: Went back in the shop on 9/5 - no purchase order - we don't know where this is / Reached out to Van Couch to understand his rental situation - 10/3 / Van reports that Pep Boys states they havent had time for someone to look at it. Calling Pep Boy's / 10/16 - Spoke to Pep Boy's earlier today and they should be getting inside today to look over it. Spoke with Tech prior so Pep Boys knows what the problems are. jchild2 | L23: Yes | N23: Yes | O23: Yes | P23: =IFERROR(VLOOKUP(D23,'TPMS-auto'!A:D, 4,0),"Not-in-TPMS") -> 0008555 | Q23: =IFERROR(VLOOKUP(Table2[[#This Row],[Unit Number]],Ops,3,0),"Not-in-TPMS") -> Monica, Cheryl & Machell | R23: =IFERROR(VLOOKUP(Table2[[#This Row],[Enterprise ID]], 'ExistingRental-12.11'!A:H, 3, 0), "Not Open On 12.11") -> 45905 | S23: =IF(Table2[[#This Row],[Start Rental Date]]="New Rental", "New Rental", "Rental Extension Request") -> Rental Extension Request | T23: =IFERROR(IF(Table2[[#This Row],[Date of this request]]-Table2[[#This Row],[Tech Service Date]]<60, "New Hire Rental", "Truck Breakdown"), "New Hire Rental") -> Truck Breakdown | U23: =IFERROR(VLOOKUP(Table2[[#This Row],[Enterprise ID]], 'ExistingRental-12.11'!A:H, 7, 0), "Not Open On 12.11") -> VAN COUCH | V23: =IFERROR(VLOOKUP(Table2[[#This Row],[Enterprise ID]],'Tech-ServiceDate'!A:B,2,0), "EitherNewHire or Termed") -> 44273
A24: 45919 | B24: 46044 | C24: Aaron Fruchey | D24: AFRUCHE | E24: =TRIM(B24) -> 46044 | F24: =IFERROR(VLOOKUP(D24,'TPMS-auto'!A:J, 10,0), "Not-in-TPMS") -> 9167076508 | G24: =IFERROR(VLOOKUP(D24,'TPMS-auto'!A:J,6,0),"Not-in-TPMS") -> 046044 | H24: 45918 | I24: 520 CONTRA COSTA BLVD, PLEASANT HILL, CA 94523 | J24: Engine made popping noise | K24: Get van repaired and tech out of rental | L24: Yes | N24: Yes | O24: Yes | P24: =IFERROR(VLOOKUP(D24,'TPMS-auto'!A:D, 4,0),"Not-in-TPMS") -> 0008184 | Q24: =IFERROR(VLOOKUP(Table2[[#This Row],[Unit Number]],Ops,3,0),"Not-in-TPMS") -> Carol & Tasha | R24: =IFERROR(VLOOKUP(Table2[[#This Row],[Enterprise ID]], 'ExistingRental-12.11'!A:H, 3, 0), "Not Open On 12.11") -> 45918 | S24: =IF(Table2[[#This Row],[Start Rental Date]]="New Rental", "New Rental", "Rental Extension Request") -> Rental Extension Request | T24: =IFERROR(IF(Table2[[#This Row],[Date of this request]]-Table2[[#This Row],[Tech Service Date]]<60, "New Hire Rental", "Truck Breakdown"), "New Hire Rental") -> Truck Breakdown | U24: =IFERROR(VLOOKUP(Table2[[#This Row],[Enterprise ID]], 'ExistingRental-12.11'!A:H, 7, 0), "Not Open On 12.11") -> AARON FRUCHEY | V24: =IFERROR(VLOOKUP(Table2[[#This Row],[Enterprise ID]],'Tech-ServiceDate'!A:B,2,0), "EitherNewHire or Termed") -> 45008
A25: 45919 | B25: 36516 | C25: Lloyd, George | D25: GLLOYD0 | E25: =TRIM(B25) -> 36516 | F25: =IFERROR(VLOOKUP(D25,'TPMS-auto'!A:J, 10,0), "Not-in-TPMS") -> 6895008458 | G25: =IFERROR(VLOOKUP(D25,'TPMS-auto'!A:J,6,0),"Not-in-TPMS") -> 036516 | H25: 45919 | I25: EXPERT CAR CARE INC., 3016 ALAFAYA TRAIL, OVIEDO FL 32765 | J25: no AC, sliding door in-op and load noise while driving | K25: Get van repaired and tech out of rental | L25: Yes | N25: Yes | O25: Yes | P25: =IFERROR(VLOOKUP(D25,'TPMS-auto'!A:D, 4,0),"Not-in-TPMS") -> 0007435 | Q25: =IFERROR(VLOOKUP(Table2[[#This Row],[Unit Number]],Ops,3,0),"Not-in-TPMS") -> Rob & Andrea | R25: =IFERROR(VLOOKUP(Table2[[#This Row],[Enterprise ID]], 'ExistingRental-12.11'!A:H, 3, 0), "Not Open On 12.11") -> 45986 | S25: =IF(Table2[[#This Row],[Start Rental Date]]="New Rental", "New Rental", "Rental Extension Request") -> Rental Extension Request | T25: =IFERROR(IF(Table2[[#This Row],[Date of this request]]-Table2[[#This Row],[Tech Service Date]]<60, "New Hire Rental", "Truck Breakdown"), "New Hire Rental") -> Truck Breakdown | U25: =IFERROR(VLOOKUP(Table2[[#This Row],[Enterprise ID]], 'ExistingRental-12.11'!A:H, 7, 0), "Not Open On 12.11") -> GEORGE LLOYD | V25: =IFERROR(VLOOKUP(Table2[[#This Row],[Enterprise ID]],'Tech-ServiceDate'!A:B,2,0), "EitherNewHire or Termed") -> 44258
A26: 45919 | B26: 23598 | C26: James Shaub | D26: JSHAUB0 | E26: =TRIM(B26) -> 23598 | F26: =IFERROR(VLOOKUP(D26,'TPMS-auto'!A:J, 10,0), "Not-in-TPMS") -> 7179167608 | G26: =IFERROR(VLOOKUP(D26,'TPMS-auto'!A:J,6,0),"Not-in-TPMS") -> 023598 | H26: 45919 | I26: PEP BOYS 1700 FRUITVILLE PIKE LANCASTER PA 17601 | J26: AC issue | K26: Get van repaired and tech out of rental | L26: Yes | N26: Yes | O26: Yes | P26: =IFERROR(VLOOKUP(D26,'TPMS-auto'!A:D, 4,0),"Not-in-TPMS") -> 0006141 | Q26: =IFERROR(VLOOKUP(Table2[[#This Row],[Unit Number]],Ops,3,0),"Not-in-TPMS") -> Monica, Cheryl & Machell | R26: =IFERROR(VLOOKUP(Table2[[#This Row],[Enterprise ID]], 'ExistingRental-12.11'!A:H, 3, 0), "Not Open On 12.11") -> Not Open On 12.11 | S26: =IF(Table2[[#This Row],[Start Rental Date]]="New Rental", "New Rental", "Rental Extension Request") -> Rental Extension Request | T26: =IFERROR(IF(Table2[[#This Row],[Date of this request]]-Table2[[#This Row],[Tech Service Date]]<60, "New Hire Rental", "Truck Breakdown"), "New Hire Rental") -> Truck Breakdown | U26: =IFERROR(VLOOKUP(Table2[[#This Row],[Enterprise ID]], 'ExistingRental-12.11'!A:H, 7, 0), "Not Open On 12.11") -> Not Open On 12.11 | V26: =IFERROR(VLOOKUP(Table2[[#This Row],[Enterprise ID]],'Tech-ServiceDate'!A:B,2,0), "EitherNewHire or Termed") -> 40583
A27: 45919 | B27: 47109 | C27: JORDAN BARTLET | D27: JBARTLE | E27: =TRIM(B27) -> 47109 | F27: =IFERROR(VLOOKUP(D27,'TPMS-auto'!A:J, 10,0), "Not-in-TPMS") -> 7189082409 | G27: =IFERROR(VLOOKUP(D27,'TPMS-auto'!A:J,6,0),"Not-in-TPMS") -> 047109 | H27: 45882 | I27: Hertz rental since 8/6 - van is repaired and paid vendor: RICHIES CITGO, 1153 WALT WHITMAN RD, MELVILLE NY 11747 | J27: New hire, Not in TPMS | K27: Assign van # 47109 to this tech and move him into it - get him out of the rental by 9/22 | L27: Yes | N27: Yes | O27: Yes | P27: =IFERROR(VLOOKUP(D27,'TPMS-auto'!A:D, 4,0),"Not-in-TPMS") -> 0007744 | Q27: =IFERROR(VLOOKUP(Table2[[#This Row],[Unit Number]],Ops,3,0),"Not-in-TPMS") -> Rob & Andrea | R27: =IFERROR(VLOOKUP(Table2[[#This Row],[Enterprise ID]], 'ExistingRental-12.11'!A:H, 3, 0), "Not Open On 12.11") -> Not Open On 12.11 | S27: =IF(Table2[[#This Row],[Start Rental Date]]="New Rental", "New Rental", "Rental Extension Request") -> Rental Extension Request | T27: =IFERROR(IF(Table2[[#This Row],[Date of this request]]-Table2[[#This Row],[Tech Service Date]]<60, "New Hire Rental", "Truck Breakdown"), "New Hire Rental") -> New Hire Rental | U27: =IFERROR(VLOOKUP(Table2[[#This Row],[Enterprise ID]], 'ExistingRental-12.11'!A:H, 7, 0), "Not Open On 12.11") -> Not Open On 12.11 | V27: =IFERROR(VLOOKUP(Table2[[#This Row],[Enterprise ID]],'Tech-ServiceDate'!A:B,2,0), "EitherNewHire or Termed") -> 45865
A28: 45919 | B28: 46838 | C28: KURTIS ELLINGER | D28: KELLIN | E28: =TRIM(B28) -> 46838 | F28: =IFERROR(VLOOKUP(D28,'TPMS-auto'!A:J, 10,0), "Not-in-TPMS") -> 7403241033 | G28: =IFERROR(VLOOKUP(D28,'TPMS-auto'!A:J,6,0),"Not-in-TPMS") -> 046838 | H28: 45878 | I28: JEFF WYLER COLUMBUS INC, 5885 GENDER RD, CANAL WINCHESTER OH 43110 | J28: Declined repair - reversing decision - will repair | K28: Repair his truck and get him back in it asap | L28: Yes | N28: Yes | O28: Yes | P28: =IFERROR(VLOOKUP(D28,'TPMS-auto'!A:D, 4,0),"Not-in-TPMS") -> 0004766 | Q28: =IFERROR(VLOOKUP(Table2[[#This Row],[Unit Number]],Ops,3,0),"Not-in-TPMS") -> Rob & Andrea | R28: =IFERROR(VLOOKUP(Table2[[#This Row],[Enterprise ID]], 'ExistingRental-12.11'!A:H, 3, 0), "Not Open On 12.11") -> 45916 | S28: =IF(Table2[[#This Row],[Start Rental Date]]="New Rental", "New Rental", "Rental Extension Request") -> Rental Extension Request | T28: =IFERROR(IF(Table2[[#This Row],[Date of this request]]-Table2[[#This Row],[Tech Service Date]]<60, "New Hire Rental", "Truck Breakdown"), "New Hire Rental") -> Truck Breakdown | U28: =IFERROR(VLOOKUP(Table2[[#This Row],[Enterprise ID]], 'ExistingRental-12.11'!A:H, 7, 0), "Not Open On 12.11") -> KURTIS ELLINGER | V28: =IFERROR(VLOOKUP(Table2[[#This Row],[Enterprise ID]],'Tech-ServiceDate'!A:B,2,0), "EitherNewHire or Termed") -> 35957
A29: 45919 | B29: 37424 | C29: PEREZ, JOSEPH | D29: JPEREZ3 | E29: =TRIM(B29) -> 37424 | F29: =IFERROR(VLOOKUP(D29,'TPMS-auto'!A:J, 10,0), "Not-in-TPMS") -> Not-in-TPMS | G29: =IFERROR(VLOOKUP(D29,'TPMS-auto'!A:J,6,0),"Not-in-TPMS") -> Not-in-TPMS | H29: 45849 | I29: Rental is on 37424 but tech is assigned 21192 - 21192 is in the shop | K29: 21192 needs to have decision reversed - install transmission and get it back to the tech asap | L29: Yes | N29: Yes | O29: Yes | P29: =IFERROR(VLOOKUP(D29,'TPMS-auto'!A:D, 4,0),"Not-in-TPMS") -> Not-in-TPMS | Q29: =IFERROR(VLOOKUP(Table2[[#This Row],[Unit Number]],Ops,3,0),"Not-in-TPMS") -> Not-in-TPMS | R29: =IFERROR(VLOOKUP(Table2[[#This Row],[Enterprise ID]], 'ExistingRental-12.11'!A:H, 3, 0), "Not Open On 12.11") -> Not Open On 12.11 | S29: =IF(Table2[[#This Row],[Start Rental Date]]="New Rental", "New Rental", "Rental Extension Request") -> Rental Extension Request | T29: =IFERROR(IF(Table2[[#This Row],[Date of this request]]-Table2[[#This Row],[Tech Service Date]]<60, "New Hire Rental", "Truck Breakdown"), "New Hire Rental") -> New Hire Rental | U29: =IFERROR(VLOOKUP(Table2[[#This Row],[Enterprise ID]], 'ExistingRental-12.11'!A:H, 7, 0), "Not Open On 12.11") -> Not Open On 12.11 | V29: =IFERROR(VLOOKUP(Table2[[#This Row],[Enterprise ID]],'Tech-ServiceDate'!A:B,2,0), "EitherNewHire or Termed") -> EitherNewHire or Termed
A30: 45919 | B30: 36780 | C30: ROBINSON, WALTER | D30: WROBINS | E30: =TRIM(B30) -> 36780 | F30: =IFERROR(VLOOKUP(D30,'TPMS-auto'!A:J, 10,0), "Not-in-TPMS") -> Not-in-TPMS | G30: =IFERROR(VLOOKUP(D30,'TPMS-auto'!A:J,6,0),"Not-in-TPMS") -> Not-in-TPMS | H30: 45849 | I30: In rental - van is in Houston, tech is in Houston - he needs to get out of rental and into the van | J30: AAMCO TOTAL CAR CARE, 10030 VETERANS MEMORIAL, HOUSTON TX 77038 | K30: Assign the van to the tech 36780 - give him time to move into the van asap | L30: Yes | N30: Yes | O30: Yes | P30: =IFERROR(VLOOKUP(D30,'TPMS-auto'!A:D, 4,0),"Not-in-TPMS") -> Not-in-TPMS | Q30: =IFERROR(VLOOKUP(Table2[[#This Row],[Unit Number]],Ops,3,0),"Not-in-TPMS") -> Not-in-TPMS | R30: =IFERROR(VLOOKUP(Table2[[#This Row],[Enterprise ID]], 'ExistingRental-12.11'!A:H, 3, 0), "Not Open On 12.11") -> Not Open On 12.11 | S30: =IF(Table2[[#This Row],[Start Rental Date]]="New Rental", "New Rental", "Rental Extension Request") -> Rental Extension Request | T30: =IFERROR(IF(Table2[[#This Row],[Date of this request]]-Table2[[#This Row],[Tech Service Date]]<60, "New Hire Rental", "Truck Breakdown"), "New Hire Rental") -> New Hire Rental | U30: =IFERROR(VLOOKUP(Table2[[#This Row],[Enterprise ID]], 'ExistingRental-12.11'!A:H, 7, 0), "Not Open On 12.11") -> Not Open On 12.11 | V30: =IFERROR(VLOOKUP(Table2[[#This Row],[Enterprise ID]],'Tech-ServiceDate'!A:B,2,0), "EitherNewHire or Termed") -> EitherNewHire or Termed
A31: 45919 | B31: 22610 | C31: Justin Setlif | D31: JSETLIF | E31: =TRIM(B31) -> 22610 | F31: =IFERROR(VLOOKUP(D31,'TPMS-auto'!A:J, 10,0), "Not-in-TPMS") -> 3367065348 | G31: =IFERROR(VLOOKUP(D31,'TPMS-auto'!A:J,6,0),"Not-in-TPMS") -> 088119 | H31: 45919 | J31: Part time new hire needs rental starting Monday | K31: Needs a permanent van | L31: Yes | N31: Yes | O31: Yes | P31: =IFERROR(VLOOKUP(D31,'TPMS-auto'!A:D, 4,0),"Not-in-TPMS") -> 0008175 | Q31: =IFERROR(VLOOKUP(Table2[[#This Row],[Unit Number]],Ops,3,0),"Not-in-TPMS") -> Rob & Andrea | R31: =IFERROR(VLOOKUP(Table2[[#This Row],[Enterprise ID]], 'ExistingRental-12.11'!A:H, 3, 0), "Not Open On 12.11") -> Not Open On 12.11 | S31: =IF(Table2[[#This Row],[Start Rental Date]]="New Rental", "New Rental", "Rental Extension Request") -> Rental Extension Request | T31: =IFERROR(IF(Table2[[#This Row],[Date of this request]]-Table2[[#This Row],[Tech Service Date]]<60, "New Hire Rental", "Truck Breakdown"), "New Hire Rental") -> New Hire Rental | U31: =IFERROR(VLOOKUP(Table2[[#This Row],[Enterprise ID]], 'ExistingRental-12.11'!A:H, 7, 0), "Not Open On 12.11") -> Not Open On 12.11 | V31: =IFERROR(VLOOKUP(Table2[[#This Row],[Enterprise ID]],'Tech-ServiceDate'!A:B,2,0), "EitherNewHire or Termed") -> 45872
A32: 45919 | B32: 61243 | C32: Fidel Magallanes | D32: FMAGA01 | E32: =TRIM(B32) -> 61243 | F32: =IFERROR(VLOOKUP(D32,'TPMS-auto'!A:J, 10,0), "Not-in-TPMS") -> 8312108140 | G32: =IFERROR(VLOOKUP(D32,'TPMS-auto'!A:J,6,0),"Not-in-TPMS") -> 061243 | H32: 45909 | I32: SALINAS VALLEY FORD/ISUZU, 1100 AUTO CENTER CIR, SALINAS CA 93907 | J32: Trans warranty | K32: Waiting for Dahmer to respond to the warranty request. That was sent off today. NO eta at this time | L32: Yes | N32: Yes | O32: Yes | P32: =IFERROR(VLOOKUP(D32,'TPMS-auto'!A:D, 4,0),"Not-in-TPMS") -> 0008366 | Q32: =IFERROR(VLOOKUP(Table2[[#This Row],[Unit Number]],Ops,3,0),"Not-in-TPMS") -> Carol & Tasha | R32: =IFERROR(VLOOKUP(Table2[[#This Row],[Enterprise ID]], 'ExistingRental-12.11'!A:H, 3, 0), "Not Open On 12.11") -> Not Open On 12.11 | S32: =IF(Table2[[#This Row],[Start Rental Date]]="New Rental", "New Rental", "Rental Extension Request") -> Rental Extension Request | T32: =IFERROR(IF(Table2[[#This Row],[Date of this request]]-Table2[[#This Row],[Tech Service Date]]<60, "New Hire Rental", "Truck Breakdown"), "New Hire Rental") -> Truck Breakdown | U32: =IFERROR(VLOOKUP(Table2[[#This Row],[Enterprise ID]], 'ExistingRental-12.11'!A:H, 7, 0), "Not Open On 12.11") -> Not Open On 12.11 | V32: =IFERROR(VLOOKUP(Table2[[#This Row],[Enterprise ID]],'Tech-ServiceDate'!A:B,2,0), "EitherNewHire or Termed") -> 37903
